{
 "cells": [
  {
   "cell_type": "markdown",
   "metadata": {},
   "source": [
    "___\n",
    "\n",
    "<a href='http://www.pieriandata.com'> <img src='../Pierian_Data_Logo.png' /></a>\n",
    "___"
   ]
  },
  {
   "cell_type": "markdown",
   "metadata": {},
   "source": [
    "# Tensorflow Project Exercise\n",
    "Let's wrap up this Deep Learning by taking a a quick look at the effectiveness of Neural Nets!\n",
    "\n",
    "We'll use the [Bank Authentication Data Set](https://archive.ics.uci.edu/ml/datasets/banknote+authentication) from the UCI repository.\n",
    "\n",
    "The data consists of 5 columns:\n",
    "\n",
    "* variance of Wavelet Transformed image (continuous)\n",
    "* skewness of Wavelet Transformed image (continuous)\n",
    "* curtosis of Wavelet Transformed image (continuous)\n",
    "* entropy of image (continuous)\n",
    "* class (integer)\n",
    "\n",
    "Where class indicates whether or not a Bank Note was authentic.\n",
    "\n",
    "This sort of task is perfectly suited for Neural Networks and Deep Learning! Just follow the instructions below to get started!"
   ]
  },
  {
   "cell_type": "markdown",
   "metadata": {},
   "source": [
    "## Get the Data\n",
    "\n",
    "** Use pandas to read in the bank_note_data.csv file **"
   ]
  },
  {
   "cell_type": "code",
   "execution_count": 16,
   "metadata": {},
   "outputs": [],
   "source": [
    "import pandas as pd\n",
    "df = pd.read_csv('bank_note_data.csv')"
   ]
  },
  {
   "cell_type": "code",
   "execution_count": 17,
   "metadata": {},
   "outputs": [
    {
     "name": "stdout",
     "output_type": "stream",
     "text": [
      "ERROR! Session/line number was not unique in database. History logging moved to new session 68\n"
     ]
    }
   ],
   "source": [
    "from sklearn.preprocessing import StandardScaler"
   ]
  },
  {
   "cell_type": "markdown",
   "metadata": {},
   "source": [
    "**Create a StandardScaler() object called scaler.**"
   ]
  },
  {
   "cell_type": "code",
   "execution_count": 18,
   "metadata": {},
   "outputs": [],
   "source": [
    "scaler = StandardScaler()"
   ]
  },
  {
   "cell_type": "markdown",
   "metadata": {},
   "source": [
    "**Fit scaler to the features.**"
   ]
  },
  {
   "cell_type": "code",
   "execution_count": 19,
   "metadata": {},
   "outputs": [],
   "source": [
    "X = df.drop('Class', axis=1)\n",
    "y = df['Class']"
   ]
  },
  {
   "cell_type": "markdown",
   "metadata": {},
   "source": [
    "**Use the .transform() method to transform the features to a scaled version.**"
   ]
  },
  {
   "cell_type": "code",
   "execution_count": 20,
   "metadata": {},
   "outputs": [
    {
     "data": {
      "text/plain": [
       "StandardScaler()"
      ]
     },
     "execution_count": 20,
     "metadata": {},
     "output_type": "execute_result"
    }
   ],
   "source": [
    "scaler.fit(X)"
   ]
  },
  {
   "cell_type": "code",
   "execution_count": 21,
   "metadata": {},
   "outputs": [],
   "source": [
    "features = scaler.fit_transform(X)"
   ]
  },
  {
   "cell_type": "code",
   "execution_count": 22,
   "metadata": {},
   "outputs": [],
   "source": [
    "df2 = pd.DataFrame(features, columns = df.columns[:-1])"
   ]
  },
  {
   "cell_type": "markdown",
   "metadata": {},
   "source": [
    "**Convert the scaled features to a dataframe and check the head of this dataframe to make sure the scaling worked.**"
   ]
  },
  {
   "cell_type": "code",
   "execution_count": 23,
   "metadata": {},
   "outputs": [
    {
     "data": {
      "text/html": [
       "<div>\n",
       "<style scoped>\n",
       "    .dataframe tbody tr th:only-of-type {\n",
       "        vertical-align: middle;\n",
       "    }\n",
       "\n",
       "    .dataframe tbody tr th {\n",
       "        vertical-align: top;\n",
       "    }\n",
       "\n",
       "    .dataframe thead th {\n",
       "        text-align: right;\n",
       "    }\n",
       "</style>\n",
       "<table border=\"1\" class=\"dataframe\">\n",
       "  <thead>\n",
       "    <tr style=\"text-align: right;\">\n",
       "      <th></th>\n",
       "      <th>Image.Var</th>\n",
       "      <th>Image.Skew</th>\n",
       "      <th>Image.Curt</th>\n",
       "      <th>Entropy</th>\n",
       "      <th>Class</th>\n",
       "    </tr>\n",
       "  </thead>\n",
       "  <tbody>\n",
       "    <tr>\n",
       "      <th>0</th>\n",
       "      <td>3.62160</td>\n",
       "      <td>8.6661</td>\n",
       "      <td>-2.8073</td>\n",
       "      <td>-0.44699</td>\n",
       "      <td>0</td>\n",
       "    </tr>\n",
       "    <tr>\n",
       "      <th>1</th>\n",
       "      <td>4.54590</td>\n",
       "      <td>8.1674</td>\n",
       "      <td>-2.4586</td>\n",
       "      <td>-1.46210</td>\n",
       "      <td>0</td>\n",
       "    </tr>\n",
       "    <tr>\n",
       "      <th>2</th>\n",
       "      <td>3.86600</td>\n",
       "      <td>-2.6383</td>\n",
       "      <td>1.9242</td>\n",
       "      <td>0.10645</td>\n",
       "      <td>0</td>\n",
       "    </tr>\n",
       "    <tr>\n",
       "      <th>3</th>\n",
       "      <td>3.45660</td>\n",
       "      <td>9.5228</td>\n",
       "      <td>-4.0112</td>\n",
       "      <td>-3.59440</td>\n",
       "      <td>0</td>\n",
       "    </tr>\n",
       "    <tr>\n",
       "      <th>4</th>\n",
       "      <td>0.32924</td>\n",
       "      <td>-4.4552</td>\n",
       "      <td>4.5718</td>\n",
       "      <td>-0.98880</td>\n",
       "      <td>0</td>\n",
       "    </tr>\n",
       "  </tbody>\n",
       "</table>\n",
       "</div>"
      ],
      "text/plain": [
       "   Image.Var  Image.Skew  Image.Curt  Entropy  Class\n",
       "0    3.62160      8.6661     -2.8073 -0.44699      0\n",
       "1    4.54590      8.1674     -2.4586 -1.46210      0\n",
       "2    3.86600     -2.6383      1.9242  0.10645      0\n",
       "3    3.45660      9.5228     -4.0112 -3.59440      0\n",
       "4    0.32924     -4.4552      4.5718 -0.98880      0"
      ]
     },
     "execution_count": 23,
     "metadata": {},
     "output_type": "execute_result"
    }
   ],
   "source": [
    "df.head()"
   ]
  },
  {
   "cell_type": "code",
   "execution_count": 24,
   "metadata": {},
   "outputs": [
    {
     "data": {
      "text/html": [
       "<div>\n",
       "<style scoped>\n",
       "    .dataframe tbody tr th:only-of-type {\n",
       "        vertical-align: middle;\n",
       "    }\n",
       "\n",
       "    .dataframe tbody tr th {\n",
       "        vertical-align: top;\n",
       "    }\n",
       "\n",
       "    .dataframe thead th {\n",
       "        text-align: right;\n",
       "    }\n",
       "</style>\n",
       "<table border=\"1\" class=\"dataframe\">\n",
       "  <thead>\n",
       "    <tr style=\"text-align: right;\">\n",
       "      <th></th>\n",
       "      <th>Image.Var</th>\n",
       "      <th>Image.Skew</th>\n",
       "      <th>Image.Curt</th>\n",
       "      <th>Entropy</th>\n",
       "    </tr>\n",
       "  </thead>\n",
       "  <tbody>\n",
       "    <tr>\n",
       "      <th>0</th>\n",
       "      <td>1.121806</td>\n",
       "      <td>1.149455</td>\n",
       "      <td>-0.975970</td>\n",
       "      <td>0.354561</td>\n",
       "    </tr>\n",
       "    <tr>\n",
       "      <th>1</th>\n",
       "      <td>1.447066</td>\n",
       "      <td>1.064453</td>\n",
       "      <td>-0.895036</td>\n",
       "      <td>-0.128767</td>\n",
       "    </tr>\n",
       "    <tr>\n",
       "      <th>2</th>\n",
       "      <td>1.207810</td>\n",
       "      <td>-0.777352</td>\n",
       "      <td>0.122218</td>\n",
       "      <td>0.618073</td>\n",
       "    </tr>\n",
       "    <tr>\n",
       "      <th>3</th>\n",
       "      <td>1.063742</td>\n",
       "      <td>1.295478</td>\n",
       "      <td>-1.255397</td>\n",
       "      <td>-1.144029</td>\n",
       "    </tr>\n",
       "    <tr>\n",
       "      <th>4</th>\n",
       "      <td>-0.036772</td>\n",
       "      <td>-1.087038</td>\n",
       "      <td>0.736730</td>\n",
       "      <td>0.096587</td>\n",
       "    </tr>\n",
       "  </tbody>\n",
       "</table>\n",
       "</div>"
      ],
      "text/plain": [
       "   Image.Var  Image.Skew  Image.Curt   Entropy\n",
       "0   1.121806    1.149455   -0.975970  0.354561\n",
       "1   1.447066    1.064453   -0.895036 -0.128767\n",
       "2   1.207810   -0.777352    0.122218  0.618073\n",
       "3   1.063742    1.295478   -1.255397 -1.144029\n",
       "4  -0.036772   -1.087038    0.736730  0.096587"
      ]
     },
     "execution_count": 24,
     "metadata": {},
     "output_type": "execute_result"
    }
   ],
   "source": [
    "df2.head()"
   ]
  },
  {
   "cell_type": "markdown",
   "metadata": {},
   "source": [
    "## Train Test Split\n",
    "\n",
    "** Create two objects X and y which are the scaled feature values and labels respectively.**"
   ]
  },
  {
   "cell_type": "code",
   "execution_count": 25,
   "metadata": {},
   "outputs": [],
   "source": [
    "from sklearn.model_selection import train_test_split\n",
    "X_train, X_test, y_train, y_test = train_test_split(features\n",
    "                                                , y, test_size=0.3)"
   ]
  },
  {
   "cell_type": "code",
   "execution_count": 26,
   "metadata": {},
   "outputs": [],
   "source": [
    "import tensorflow as tf"
   ]
  },
  {
   "cell_type": "markdown",
   "metadata": {},
   "source": [
    "** Use SciKit Learn to create training and testing sets of the data as we've done in previous lectures:**"
   ]
  },
  {
   "cell_type": "code",
   "execution_count": null,
   "metadata": {},
   "outputs": [
    {
     "name": "stderr",
     "output_type": "stream",
     "text": [
      "ERROR:root:Internal Python error in the inspect module.\n",
      "Below is the traceback from this internal error.\n",
      "\n",
      "ERROR:root:Internal Python error in the inspect module.\n",
      "Below is the traceback from this internal error.\n",
      "\n",
      "ERROR:root:Internal Python error in the inspect module.\n",
      "Below is the traceback from this internal error.\n",
      "\n"
     ]
    },
    {
     "name": "stdout",
     "output_type": "stream",
     "text": [
      "Traceback (most recent call last):\n",
      "  File \"C:\\Users\\thecl\\anaconda3\\envs\\tf1_env\\lib\\site-packages\\IPython\\core\\interactiveshell.py\", line 3457, in run_code\n",
      "    exec(code_obj, self.user_global_ns, self.user_ns)\n",
      "  File \"C:\\Users\\thecl\\AppData\\Local\\Temp\\ipykernel_21112\\773928935.py\", line 1, in <module>\n",
      "    image_var = tf.feature_column.numeric_column('Image.Var')\n",
      "  File \"C:\\Users\\thecl\\anaconda3\\envs\\tf1_env\\lib\\site-packages\\tensorflow_core\\python\\util\\module_wrapper.py\", line 193, in __getattr__\n",
      "    attr = getattr(self._tfmw_wrapped_module, name)\n",
      "AttributeError: module 'tensorflow' has no attribute 'feature_column'\n",
      "\n",
      "During handling of the above exception, another exception occurred:\n",
      "\n",
      "Traceback (most recent call last):\n",
      "  File \"C:\\Users\\thecl\\anaconda3\\envs\\tf1_env\\lib\\site-packages\\IPython\\core\\interactiveshell.py\", line 2077, in showtraceback\n",
      "    stb = value._render_traceback_()\n",
      "AttributeError: 'AttributeError' object has no attribute '_render_traceback_'\n",
      "\n",
      "During handling of the above exception, another exception occurred:\n",
      "\n",
      "Traceback (most recent call last):\n",
      "  File \"C:\\Users\\thecl\\anaconda3\\envs\\tf1_env\\lib\\site-packages\\IPython\\core\\ultratb.py\", line 1101, in get_records\n",
      "    return _fixed_getinnerframes(etb, number_of_lines_of_context, tb_offset)\n",
      "  File \"C:\\Users\\thecl\\anaconda3\\envs\\tf1_env\\lib\\site-packages\\IPython\\core\\ultratb.py\", line 248, in wrapped\n",
      "    return f(*args, **kwargs)\n",
      "  File \"C:\\Users\\thecl\\anaconda3\\envs\\tf1_env\\lib\\site-packages\\IPython\\core\\ultratb.py\", line 281, in _fixed_getinnerframes\n",
      "    records = fix_frame_records_filenames(inspect.getinnerframes(etb, context))\n",
      "  File \"C:\\Users\\thecl\\anaconda3\\envs\\tf1_env\\lib\\inspect.py\", line 1500, in getinnerframes\n",
      "    frameinfo = (tb.tb_frame,) + getframeinfo(tb, context)\n",
      "  File \"C:\\Users\\thecl\\anaconda3\\envs\\tf1_env\\lib\\inspect.py\", line 1458, in getframeinfo\n",
      "    filename = getsourcefile(frame) or getfile(frame)\n",
      "  File \"C:\\Users\\thecl\\anaconda3\\envs\\tf1_env\\lib\\inspect.py\", line 696, in getsourcefile\n",
      "    if getattr(getmodule(object, filename), '__loader__', None) is not None:\n",
      "  File \"C:\\Users\\thecl\\anaconda3\\envs\\tf1_env\\lib\\inspect.py\", line 733, in getmodule\n",
      "    if ismodule(module) and hasattr(module, '__file__'):\n",
      "  File \"C:\\Users\\thecl\\anaconda3\\envs\\tf1_env\\lib\\site-packages\\tensorflow\\__init__.py\", line 50, in __getattr__\n",
      "    module = self._load()\n",
      "  File \"C:\\Users\\thecl\\anaconda3\\envs\\tf1_env\\lib\\site-packages\\tensorflow\\__init__.py\", line 44, in _load\n",
      "    module = _importlib.import_module(self.__name__)\n",
      "  File \"C:\\Users\\thecl\\anaconda3\\envs\\tf1_env\\lib\\importlib\\__init__.py\", line 127, in import_module\n",
      "    return _bootstrap._gcd_import(name[level:], package, level)\n",
      "  File \"<frozen importlib._bootstrap>\", line 1006, in _gcd_import\n",
      "  File \"<frozen importlib._bootstrap>\", line 983, in _find_and_load\n",
      "  File \"<frozen importlib._bootstrap>\", line 953, in _find_and_load_unlocked\n",
      "  File \"<frozen importlib._bootstrap>\", line 219, in _call_with_frames_removed\n",
      "  File \"<frozen importlib._bootstrap>\", line 1006, in _gcd_import\n",
      "  File \"<frozen importlib._bootstrap>\", line 983, in _find_and_load\n",
      "  File \"<frozen importlib._bootstrap>\", line 967, in _find_and_load_unlocked\n",
      "  File \"<frozen importlib._bootstrap>\", line 677, in _load_unlocked\n",
      "  File \"<frozen importlib._bootstrap_external>\", line 728, in exec_module\n",
      "  File \"<frozen importlib._bootstrap>\", line 219, in _call_with_frames_removed\n",
      "  File \"C:\\Users\\thecl\\anaconda3\\envs\\tf1_env\\lib\\site-packages\\tensorflow_core\\__init__.py\", line 33, in <module>\n",
      "    from tensorflow._api.v1 import audio\n",
      "  File \"C:\\Users\\thecl\\anaconda3\\envs\\tf1_env\\lib\\site-packages\\tensorflow_core\\_api\\v1\\audio\\__init__.py\", line 10, in <module>\n",
      "    from tensorflow.python.ops.gen_audio_ops import decode_wav\n",
      "  File \"C:\\Users\\thecl\\anaconda3\\envs\\tf1_env\\lib\\site-packages\\tensorflow_core\\python\\ops\\gen_audio_ops.py\", line 11, in <module>\n",
      "    from tensorflow.python.eager import context as _context\n",
      "  File \"C:\\Users\\thecl\\anaconda3\\envs\\tf1_env\\lib\\site-packages\\tensorflow_core\\python\\eager\\context.py\", line 29, in <module>\n",
      "    from tensorflow.core.protobuf import config_pb2\n",
      "  File \"C:\\Users\\thecl\\anaconda3\\envs\\tf1_env\\lib\\site-packages\\tensorflow_core\\core\\protobuf\\config_pb2.py\", line 16, in <module>\n",
      "    from tensorflow.core.framework import cost_graph_pb2 as tensorflow_dot_core_dot_framework_dot_cost__graph__pb2\n",
      "  File \"C:\\Users\\thecl\\anaconda3\\envs\\tf1_env\\lib\\site-packages\\tensorflow_core\\core\\framework\\cost_graph_pb2.py\", line 16, in <module>\n",
      "    from tensorflow.core.framework import tensor_shape_pb2 as tensorflow_dot_core_dot_framework_dot_tensor__shape__pb2\n",
      "  File \"C:\\Users\\thecl\\anaconda3\\envs\\tf1_env\\lib\\site-packages\\tensorflow_core\\core\\framework\\tensor_shape_pb2.py\", line 42, in <module>\n",
      "    serialized_options=None, file=DESCRIPTOR),\n",
      "  File \"C:\\Users\\thecl\\anaconda3\\envs\\tf1_env\\lib\\site-packages\\google\\protobuf\\descriptor.py\", line 561, in __new__\n",
      "    _message.Message._CheckCalledFromGeneratedFile()\n",
      "TypeError: Descriptors cannot not be created directly.\n",
      "If this call came from a _pb2.py file, your generated code is out of date and must be regenerated with protoc >= 3.19.0.\n",
      "If you cannot immediately regenerate your protos, some other possible workarounds are:\n",
      " 1. Downgrade the protobuf package to 3.20.x or lower.\n",
      " 2. Set PROTOCOL_BUFFERS_PYTHON_IMPLEMENTATION=python (but this will use pure-Python parsing and will be much slower).\n",
      "\n",
      "More information: https://developers.google.com/protocol-buffers/docs/news/2022-05-06#python-updates\n",
      "Traceback (most recent call last):\n",
      "  File \"C:\\Users\\thecl\\anaconda3\\envs\\tf1_env\\lib\\site-packages\\IPython\\core\\interactiveshell.py\", line 3457, in run_code\n",
      "    exec(code_obj, self.user_global_ns, self.user_ns)\n",
      "  File \"C:\\Users\\thecl\\AppData\\Local\\Temp\\ipykernel_21112\\773928935.py\", line 1, in <module>\n",
      "    image_var = tf.feature_column.numeric_column('Image.Var')\n",
      "  File \"C:\\Users\\thecl\\anaconda3\\envs\\tf1_env\\lib\\site-packages\\tensorflow_core\\python\\util\\module_wrapper.py\", line 193, in __getattr__\n",
      "    attr = getattr(self._tfmw_wrapped_module, name)\n",
      "AttributeError: module 'tensorflow' has no attribute 'feature_column'\n",
      "\n",
      "During handling of the above exception, another exception occurred:\n",
      "\n",
      "Traceback (most recent call last):\n",
      "  File \"C:\\Users\\thecl\\anaconda3\\envs\\tf1_env\\lib\\site-packages\\IPython\\core\\interactiveshell.py\", line 2077, in showtraceback\n",
      "    stb = value._render_traceback_()\n",
      "AttributeError: 'AttributeError' object has no attribute '_render_traceback_'\n",
      "\n",
      "During handling of the above exception, another exception occurred:\n",
      "\n",
      "Traceback (most recent call last):\n",
      "  File \"C:\\Users\\thecl\\anaconda3\\envs\\tf1_env\\lib\\site-packages\\IPython\\core\\interactiveshell.py\", line 3377, in run_ast_nodes\n",
      "    if (await self.run_code(code, result,  async_=asy)):\n",
      "  File \"C:\\Users\\thecl\\anaconda3\\envs\\tf1_env\\lib\\site-packages\\IPython\\core\\interactiveshell.py\", line 3474, in run_code\n",
      "    self.showtraceback(running_compiled_code=True)\n",
      "  File \"C:\\Users\\thecl\\anaconda3\\envs\\tf1_env\\lib\\site-packages\\IPython\\core\\interactiveshell.py\", line 2080, in showtraceback\n",
      "    value, tb, tb_offset=tb_offset)\n",
      "  File \"C:\\Users\\thecl\\anaconda3\\envs\\tf1_env\\lib\\site-packages\\IPython\\core\\ultratb.py\", line 1368, in structured_traceback\n",
      "    self, etype, value, tb, tb_offset, number_of_lines_of_context)\n",
      "  File \"C:\\Users\\thecl\\anaconda3\\envs\\tf1_env\\lib\\site-packages\\IPython\\core\\ultratb.py\", line 1268, in structured_traceback\n",
      "    self, etype, value, tb, tb_offset, number_of_lines_of_context\n",
      "  File \"C:\\Users\\thecl\\anaconda3\\envs\\tf1_env\\lib\\site-packages\\IPython\\core\\ultratb.py\", line 1125, in structured_traceback\n",
      "    tb_offset)\n",
      "  File \"C:\\Users\\thecl\\anaconda3\\envs\\tf1_env\\lib\\site-packages\\IPython\\core\\ultratb.py\", line 1082, in format_exception_as_a_whole\n",
      "    last_unique, recursion_repeat = find_recursion(orig_etype, evalue, records)\n",
      "  File \"C:\\Users\\thecl\\anaconda3\\envs\\tf1_env\\lib\\site-packages\\IPython\\core\\ultratb.py\", line 382, in find_recursion\n",
      "    return len(records), 0\n",
      "TypeError: object of type 'NoneType' has no len()\n",
      "\n",
      "During handling of the above exception, another exception occurred:\n",
      "\n",
      "Traceback (most recent call last):\n",
      "  File \"C:\\Users\\thecl\\anaconda3\\envs\\tf1_env\\lib\\site-packages\\IPython\\core\\interactiveshell.py\", line 2077, in showtraceback\n",
      "    stb = value._render_traceback_()\n",
      "AttributeError: 'TypeError' object has no attribute '_render_traceback_'\n",
      "\n",
      "During handling of the above exception, another exception occurred:\n",
      "\n",
      "Traceback (most recent call last):\n",
      "  File \"C:\\Users\\thecl\\anaconda3\\envs\\tf1_env\\lib\\site-packages\\IPython\\core\\ultratb.py\", line 1101, in get_records\n",
      "    return _fixed_getinnerframes(etb, number_of_lines_of_context, tb_offset)\n",
      "  File \"C:\\Users\\thecl\\anaconda3\\envs\\tf1_env\\lib\\site-packages\\IPython\\core\\ultratb.py\", line 248, in wrapped\n",
      "    return f(*args, **kwargs)\n",
      "  File \"C:\\Users\\thecl\\anaconda3\\envs\\tf1_env\\lib\\site-packages\\IPython\\core\\ultratb.py\", line 281, in _fixed_getinnerframes\n",
      "    records = fix_frame_records_filenames(inspect.getinnerframes(etb, context))\n",
      "  File \"C:\\Users\\thecl\\anaconda3\\envs\\tf1_env\\lib\\inspect.py\", line 1500, in getinnerframes\n",
      "    frameinfo = (tb.tb_frame,) + getframeinfo(tb, context)\n",
      "  File \"C:\\Users\\thecl\\anaconda3\\envs\\tf1_env\\lib\\inspect.py\", line 1458, in getframeinfo\n",
      "    filename = getsourcefile(frame) or getfile(frame)\n",
      "  File \"C:\\Users\\thecl\\anaconda3\\envs\\tf1_env\\lib\\inspect.py\", line 696, in getsourcefile\n",
      "    if getattr(getmodule(object, filename), '__loader__', None) is not None:\n",
      "  File \"C:\\Users\\thecl\\anaconda3\\envs\\tf1_env\\lib\\inspect.py\", line 733, in getmodule\n",
      "    if ismodule(module) and hasattr(module, '__file__'):\n",
      "  File \"C:\\Users\\thecl\\anaconda3\\envs\\tf1_env\\lib\\site-packages\\tensorflow\\__init__.py\", line 50, in __getattr__\n",
      "    module = self._load()\n",
      "  File \"C:\\Users\\thecl\\anaconda3\\envs\\tf1_env\\lib\\site-packages\\tensorflow\\__init__.py\", line 44, in _load\n",
      "    module = _importlib.import_module(self.__name__)\n",
      "  File \"C:\\Users\\thecl\\anaconda3\\envs\\tf1_env\\lib\\importlib\\__init__.py\", line 127, in import_module\n",
      "    return _bootstrap._gcd_import(name[level:], package, level)\n",
      "  File \"<frozen importlib._bootstrap>\", line 1006, in _gcd_import\n",
      "  File \"<frozen importlib._bootstrap>\", line 983, in _find_and_load\n",
      "  File \"<frozen importlib._bootstrap>\", line 953, in _find_and_load_unlocked\n",
      "  File \"<frozen importlib._bootstrap>\", line 219, in _call_with_frames_removed\n",
      "  File \"<frozen importlib._bootstrap>\", line 1006, in _gcd_import\n",
      "  File \"<frozen importlib._bootstrap>\", line 983, in _find_and_load\n",
      "  File \"<frozen importlib._bootstrap>\", line 967, in _find_and_load_unlocked\n",
      "  File \"<frozen importlib._bootstrap>\", line 677, in _load_unlocked\n",
      "  File \"<frozen importlib._bootstrap_external>\", line 728, in exec_module\n",
      "  File \"<frozen importlib._bootstrap>\", line 219, in _call_with_frames_removed\n",
      "  File \"C:\\Users\\thecl\\anaconda3\\envs\\tf1_env\\lib\\site-packages\\tensorflow_core\\__init__.py\", line 33, in <module>\n",
      "    from tensorflow._api.v1 import audio\n",
      "  File \"C:\\Users\\thecl\\anaconda3\\envs\\tf1_env\\lib\\site-packages\\tensorflow_core\\_api\\v1\\audio\\__init__.py\", line 10, in <module>\n",
      "    from tensorflow.python.ops.gen_audio_ops import decode_wav\n",
      "  File \"C:\\Users\\thecl\\anaconda3\\envs\\tf1_env\\lib\\site-packages\\tensorflow_core\\python\\ops\\gen_audio_ops.py\", line 11, in <module>\n",
      "    from tensorflow.python.eager import context as _context\n",
      "  File \"C:\\Users\\thecl\\anaconda3\\envs\\tf1_env\\lib\\site-packages\\tensorflow_core\\python\\eager\\context.py\", line 29, in <module>\n",
      "    from tensorflow.core.protobuf import config_pb2\n",
      "  File \"C:\\Users\\thecl\\anaconda3\\envs\\tf1_env\\lib\\site-packages\\tensorflow_core\\core\\protobuf\\config_pb2.py\", line 16, in <module>\n",
      "    from tensorflow.core.framework import cost_graph_pb2 as tensorflow_dot_core_dot_framework_dot_cost__graph__pb2\n",
      "  File \"C:\\Users\\thecl\\anaconda3\\envs\\tf1_env\\lib\\site-packages\\tensorflow_core\\core\\framework\\cost_graph_pb2.py\", line 16, in <module>\n",
      "    from tensorflow.core.framework import tensor_shape_pb2 as tensorflow_dot_core_dot_framework_dot_tensor__shape__pb2\n",
      "  File \"C:\\Users\\thecl\\anaconda3\\envs\\tf1_env\\lib\\site-packages\\tensorflow_core\\core\\framework\\tensor_shape_pb2.py\", line 42, in <module>\n",
      "    serialized_options=None, file=DESCRIPTOR),\n",
      "  File \"C:\\Users\\thecl\\anaconda3\\envs\\tf1_env\\lib\\site-packages\\google\\protobuf\\descriptor.py\", line 561, in __new__\n",
      "    _message.Message._CheckCalledFromGeneratedFile()\n",
      "TypeError: Descriptors cannot not be created directly.\n",
      "If this call came from a _pb2.py file, your generated code is out of date and must be regenerated with protoc >= 3.19.0.\n",
      "If you cannot immediately regenerate your protos, some other possible workarounds are:\n",
      " 1. Downgrade the protobuf package to 3.20.x or lower.\n",
      " 2. Set PROTOCOL_BUFFERS_PYTHON_IMPLEMENTATION=python (but this will use pure-Python parsing and will be much slower).\n",
      "\n",
      "More information: https://developers.google.com/protocol-buffers/docs/news/2022-05-06#python-updates\n",
      "Traceback (most recent call last):\n",
      "  File \"C:\\Users\\thecl\\anaconda3\\envs\\tf1_env\\lib\\site-packages\\IPython\\core\\interactiveshell.py\", line 3457, in run_code\n",
      "    exec(code_obj, self.user_global_ns, self.user_ns)\n",
      "  File \"C:\\Users\\thecl\\AppData\\Local\\Temp\\ipykernel_21112\\773928935.py\", line 1, in <module>\n",
      "    image_var = tf.feature_column.numeric_column('Image.Var')\n",
      "  File \"C:\\Users\\thecl\\anaconda3\\envs\\tf1_env\\lib\\site-packages\\tensorflow_core\\python\\util\\module_wrapper.py\", line 193, in __getattr__\n",
      "    attr = getattr(self._tfmw_wrapped_module, name)\n",
      "AttributeError: module 'tensorflow' has no attribute 'feature_column'\n",
      "\n",
      "During handling of the above exception, another exception occurred:\n",
      "\n",
      "Traceback (most recent call last):\n",
      "  File \"C:\\Users\\thecl\\anaconda3\\envs\\tf1_env\\lib\\site-packages\\IPython\\core\\interactiveshell.py\", line 2077, in showtraceback\n",
      "    stb = value._render_traceback_()\n",
      "AttributeError: 'AttributeError' object has no attribute '_render_traceback_'\n",
      "\n",
      "During handling of the above exception, another exception occurred:\n",
      "\n",
      "Traceback (most recent call last):\n",
      "  File \"C:\\Users\\thecl\\anaconda3\\envs\\tf1_env\\lib\\site-packages\\IPython\\core\\interactiveshell.py\", line 3377, in run_ast_nodes\n",
      "    if (await self.run_code(code, result,  async_=asy)):\n",
      "  File \"C:\\Users\\thecl\\anaconda3\\envs\\tf1_env\\lib\\site-packages\\IPython\\core\\interactiveshell.py\", line 3474, in run_code\n",
      "    self.showtraceback(running_compiled_code=True)\n",
      "  File \"C:\\Users\\thecl\\anaconda3\\envs\\tf1_env\\lib\\site-packages\\IPython\\core\\interactiveshell.py\", line 2080, in showtraceback\n",
      "    value, tb, tb_offset=tb_offset)\n",
      "  File \"C:\\Users\\thecl\\anaconda3\\envs\\tf1_env\\lib\\site-packages\\IPython\\core\\ultratb.py\", line 1368, in structured_traceback\n",
      "    self, etype, value, tb, tb_offset, number_of_lines_of_context)\n",
      "  File \"C:\\Users\\thecl\\anaconda3\\envs\\tf1_env\\lib\\site-packages\\IPython\\core\\ultratb.py\", line 1268, in structured_traceback\n",
      "    self, etype, value, tb, tb_offset, number_of_lines_of_context\n",
      "  File \"C:\\Users\\thecl\\anaconda3\\envs\\tf1_env\\lib\\site-packages\\IPython\\core\\ultratb.py\", line 1125, in structured_traceback\n",
      "    tb_offset)\n",
      "  File \"C:\\Users\\thecl\\anaconda3\\envs\\tf1_env\\lib\\site-packages\\IPython\\core\\ultratb.py\", line 1082, in format_exception_as_a_whole\n",
      "    last_unique, recursion_repeat = find_recursion(orig_etype, evalue, records)\n",
      "  File \"C:\\Users\\thecl\\anaconda3\\envs\\tf1_env\\lib\\site-packages\\IPython\\core\\ultratb.py\", line 382, in find_recursion\n",
      "    return len(records), 0\n",
      "TypeError: object of type 'NoneType' has no len()\n",
      "\n",
      "During handling of the above exception, another exception occurred:\n",
      "\n",
      "Traceback (most recent call last):\n",
      "  File \"C:\\Users\\thecl\\anaconda3\\envs\\tf1_env\\lib\\site-packages\\IPython\\core\\interactiveshell.py\", line 2077, in showtraceback\n",
      "    stb = value._render_traceback_()\n",
      "AttributeError: 'TypeError' object has no attribute '_render_traceback_'\n",
      "\n",
      "During handling of the above exception, another exception occurred:\n",
      "\n",
      "Traceback (most recent call last):\n",
      "  File \"C:\\Users\\thecl\\anaconda3\\envs\\tf1_env\\lib\\site-packages\\IPython\\core\\interactiveshell.py\", line 2960, in _run_cell\n",
      "    return runner(coro)\n",
      "  File \"C:\\Users\\thecl\\anaconda3\\envs\\tf1_env\\lib\\site-packages\\IPython\\core\\async_helpers.py\", line 78, in _pseudo_sync_runner\n",
      "    coro.send(None)\n",
      "  File \"C:\\Users\\thecl\\anaconda3\\envs\\tf1_env\\lib\\site-packages\\IPython\\core\\interactiveshell.py\", line 3186, in run_cell_async\n",
      "    interactivity=interactivity, compiler=compiler, result=result)\n",
      "  File \"C:\\Users\\thecl\\anaconda3\\envs\\tf1_env\\lib\\site-packages\\IPython\\core\\interactiveshell.py\", line 3396, in run_ast_nodes\n",
      "    self.showtraceback()\n",
      "  File \"C:\\Users\\thecl\\anaconda3\\envs\\tf1_env\\lib\\site-packages\\IPython\\core\\interactiveshell.py\", line 2080, in showtraceback\n",
      "    value, tb, tb_offset=tb_offset)\n",
      "  File \"C:\\Users\\thecl\\anaconda3\\envs\\tf1_env\\lib\\site-packages\\IPython\\core\\ultratb.py\", line 1368, in structured_traceback\n",
      "    self, etype, value, tb, tb_offset, number_of_lines_of_context)\n",
      "  File \"C:\\Users\\thecl\\anaconda3\\envs\\tf1_env\\lib\\site-packages\\IPython\\core\\ultratb.py\", line 1268, in structured_traceback\n",
      "    self, etype, value, tb, tb_offset, number_of_lines_of_context\n",
      "  File \"C:\\Users\\thecl\\anaconda3\\envs\\tf1_env\\lib\\site-packages\\IPython\\core\\ultratb.py\", line 1143, in structured_traceback\n",
      "    chained_exceptions_tb_offset)\n",
      "  File \"C:\\Users\\thecl\\anaconda3\\envs\\tf1_env\\lib\\site-packages\\IPython\\core\\ultratb.py\", line 1082, in format_exception_as_a_whole\n",
      "    last_unique, recursion_repeat = find_recursion(orig_etype, evalue, records)\n",
      "  File \"C:\\Users\\thecl\\anaconda3\\envs\\tf1_env\\lib\\site-packages\\IPython\\core\\ultratb.py\", line 382, in find_recursion\n",
      "    return len(records), 0\n",
      "TypeError: object of type 'NoneType' has no len()\n",
      "\n",
      "During handling of the above exception, another exception occurred:\n",
      "\n",
      "Traceback (most recent call last):\n",
      "  File \"C:\\Users\\thecl\\anaconda3\\envs\\tf1_env\\lib\\site-packages\\IPython\\core\\interactiveshell.py\", line 2077, in showtraceback\n",
      "    stb = value._render_traceback_()\n",
      "AttributeError: 'TypeError' object has no attribute '_render_traceback_'\n",
      "\n",
      "During handling of the above exception, another exception occurred:\n",
      "\n",
      "Traceback (most recent call last):\n",
      "  File \"C:\\Users\\thecl\\anaconda3\\envs\\tf1_env\\lib\\site-packages\\IPython\\core\\ultratb.py\", line 1101, in get_records\n",
      "    return _fixed_getinnerframes(etb, number_of_lines_of_context, tb_offset)\n",
      "  File \"C:\\Users\\thecl\\anaconda3\\envs\\tf1_env\\lib\\site-packages\\IPython\\core\\ultratb.py\", line 248, in wrapped\n",
      "    return f(*args, **kwargs)\n",
      "  File \"C:\\Users\\thecl\\anaconda3\\envs\\tf1_env\\lib\\site-packages\\IPython\\core\\ultratb.py\", line 281, in _fixed_getinnerframes\n",
      "    records = fix_frame_records_filenames(inspect.getinnerframes(etb, context))\n",
      "  File \"C:\\Users\\thecl\\anaconda3\\envs\\tf1_env\\lib\\inspect.py\", line 1500, in getinnerframes\n",
      "    frameinfo = (tb.tb_frame,) + getframeinfo(tb, context)\n",
      "  File \"C:\\Users\\thecl\\anaconda3\\envs\\tf1_env\\lib\\inspect.py\", line 1458, in getframeinfo\n",
      "    filename = getsourcefile(frame) or getfile(frame)\n",
      "  File \"C:\\Users\\thecl\\anaconda3\\envs\\tf1_env\\lib\\inspect.py\", line 696, in getsourcefile\n",
      "    if getattr(getmodule(object, filename), '__loader__', None) is not None:\n",
      "  File \"C:\\Users\\thecl\\anaconda3\\envs\\tf1_env\\lib\\inspect.py\", line 733, in getmodule\n",
      "    if ismodule(module) and hasattr(module, '__file__'):\n",
      "  File \"C:\\Users\\thecl\\anaconda3\\envs\\tf1_env\\lib\\site-packages\\tensorflow\\__init__.py\", line 50, in __getattr__\n",
      "    module = self._load()\n",
      "  File \"C:\\Users\\thecl\\anaconda3\\envs\\tf1_env\\lib\\site-packages\\tensorflow\\__init__.py\", line 44, in _load\n",
      "    module = _importlib.import_module(self.__name__)\n",
      "  File \"C:\\Users\\thecl\\anaconda3\\envs\\tf1_env\\lib\\importlib\\__init__.py\", line 127, in import_module\n",
      "    return _bootstrap._gcd_import(name[level:], package, level)\n",
      "  File \"<frozen importlib._bootstrap>\", line 1006, in _gcd_import\n",
      "  File \"<frozen importlib._bootstrap>\", line 983, in _find_and_load\n",
      "  File \"<frozen importlib._bootstrap>\", line 953, in _find_and_load_unlocked\n",
      "  File \"<frozen importlib._bootstrap>\", line 219, in _call_with_frames_removed\n",
      "  File \"<frozen importlib._bootstrap>\", line 1006, in _gcd_import\n",
      "  File \"<frozen importlib._bootstrap>\", line 983, in _find_and_load\n",
      "  File \"<frozen importlib._bootstrap>\", line 967, in _find_and_load_unlocked\n",
      "  File \"<frozen importlib._bootstrap>\", line 677, in _load_unlocked\n",
      "  File \"<frozen importlib._bootstrap_external>\", line 728, in exec_module\n",
      "  File \"<frozen importlib._bootstrap>\", line 219, in _call_with_frames_removed\n",
      "  File \"C:\\Users\\thecl\\anaconda3\\envs\\tf1_env\\lib\\site-packages\\tensorflow_core\\__init__.py\", line 33, in <module>\n",
      "    from tensorflow._api.v1 import audio\n",
      "  File \"C:\\Users\\thecl\\anaconda3\\envs\\tf1_env\\lib\\site-packages\\tensorflow_core\\_api\\v1\\audio\\__init__.py\", line 10, in <module>\n",
      "    from tensorflow.python.ops.gen_audio_ops import decode_wav\n",
      "  File \"C:\\Users\\thecl\\anaconda3\\envs\\tf1_env\\lib\\site-packages\\tensorflow_core\\python\\ops\\gen_audio_ops.py\", line 11, in <module>\n",
      "    from tensorflow.python.eager import context as _context\n",
      "  File \"C:\\Users\\thecl\\anaconda3\\envs\\tf1_env\\lib\\site-packages\\tensorflow_core\\python\\eager\\context.py\", line 29, in <module>\n",
      "    from tensorflow.core.protobuf import config_pb2\n",
      "  File \"C:\\Users\\thecl\\anaconda3\\envs\\tf1_env\\lib\\site-packages\\tensorflow_core\\core\\protobuf\\config_pb2.py\", line 16, in <module>\n",
      "    from tensorflow.core.framework import cost_graph_pb2 as tensorflow_dot_core_dot_framework_dot_cost__graph__pb2\n",
      "  File \"C:\\Users\\thecl\\anaconda3\\envs\\tf1_env\\lib\\site-packages\\tensorflow_core\\core\\framework\\cost_graph_pb2.py\", line 16, in <module>\n",
      "    from tensorflow.core.framework import tensor_shape_pb2 as tensorflow_dot_core_dot_framework_dot_tensor__shape__pb2\n",
      "  File \"C:\\Users\\thecl\\anaconda3\\envs\\tf1_env\\lib\\site-packages\\tensorflow_core\\core\\framework\\tensor_shape_pb2.py\", line 42, in <module>\n",
      "    serialized_options=None, file=DESCRIPTOR),\n",
      "  File \"C:\\Users\\thecl\\anaconda3\\envs\\tf1_env\\lib\\site-packages\\google\\protobuf\\descriptor.py\", line 561, in __new__\n",
      "    _message.Message._CheckCalledFromGeneratedFile()\n",
      "TypeError: Descriptors cannot not be created directly.\n",
      "If this call came from a _pb2.py file, your generated code is out of date and must be regenerated with protoc >= 3.19.0.\n",
      "If you cannot immediately regenerate your protos, some other possible workarounds are:\n",
      " 1. Downgrade the protobuf package to 3.20.x or lower.\n",
      " 2. Set PROTOCOL_BUFFERS_PYTHON_IMPLEMENTATION=python (but this will use pure-Python parsing and will be much slower).\n",
      "\n",
      "More information: https://developers.google.com/protocol-buffers/docs/news/2022-05-06#python-updates\n"
     ]
    }
   ],
   "source": [
    "image_var = tf.feature_column.numeric_column('Image.Var')\n",
    "image_skew = tf.feature_column.numeric_column('Image.Skew')\n",
    "image_curt = tf.feature_column.numeric_column('Image.Curt')\n",
    "entropy = tf.feature_column.numeric_column('Entropy')"
   ]
  },
  {
   "cell_type": "code",
   "execution_count": null,
   "metadata": {},
   "outputs": [
    {
     "name": "stderr",
     "output_type": "stream",
     "text": [
      "ERROR:root:Internal Python error in the inspect module.\n",
      "Below is the traceback from this internal error.\n",
      "\n",
      "ERROR:root:Internal Python error in the inspect module.\n",
      "Below is the traceback from this internal error.\n",
      "\n",
      "ERROR:root:Internal Python error in the inspect module.\n",
      "Below is the traceback from this internal error.\n",
      "\n"
     ]
    },
    {
     "name": "stdout",
     "output_type": "stream",
     "text": [
      "Traceback (most recent call last):\n",
      "  File \"C:\\Users\\thecl\\anaconda3\\envs\\tf1_env\\lib\\site-packages\\IPython\\core\\interactiveshell.py\", line 3457, in run_code\n",
      "    exec(code_obj, self.user_global_ns, self.user_ns)\n",
      "  File \"C:\\Users\\thecl\\AppData\\Local\\Temp\\ipykernel_21112\\66615791.py\", line 1, in <module>\n",
      "    feat_cols = [image_var, image_skew, image_curt, entropy]\n",
      "NameError: name 'image_var' is not defined\n",
      "\n",
      "During handling of the above exception, another exception occurred:\n",
      "\n",
      "Traceback (most recent call last):\n",
      "  File \"C:\\Users\\thecl\\anaconda3\\envs\\tf1_env\\lib\\site-packages\\IPython\\core\\interactiveshell.py\", line 2077, in showtraceback\n",
      "    stb = value._render_traceback_()\n",
      "AttributeError: 'NameError' object has no attribute '_render_traceback_'\n",
      "\n",
      "During handling of the above exception, another exception occurred:\n",
      "\n",
      "Traceback (most recent call last):\n",
      "  File \"C:\\Users\\thecl\\anaconda3\\envs\\tf1_env\\lib\\site-packages\\IPython\\core\\ultratb.py\", line 1101, in get_records\n",
      "    return _fixed_getinnerframes(etb, number_of_lines_of_context, tb_offset)\n",
      "  File \"C:\\Users\\thecl\\anaconda3\\envs\\tf1_env\\lib\\site-packages\\IPython\\core\\ultratb.py\", line 248, in wrapped\n",
      "    return f(*args, **kwargs)\n",
      "  File \"C:\\Users\\thecl\\anaconda3\\envs\\tf1_env\\lib\\site-packages\\IPython\\core\\ultratb.py\", line 281, in _fixed_getinnerframes\n",
      "    records = fix_frame_records_filenames(inspect.getinnerframes(etb, context))\n",
      "  File \"C:\\Users\\thecl\\anaconda3\\envs\\tf1_env\\lib\\inspect.py\", line 1500, in getinnerframes\n",
      "    frameinfo = (tb.tb_frame,) + getframeinfo(tb, context)\n",
      "  File \"C:\\Users\\thecl\\anaconda3\\envs\\tf1_env\\lib\\inspect.py\", line 1458, in getframeinfo\n",
      "    filename = getsourcefile(frame) or getfile(frame)\n",
      "  File \"C:\\Users\\thecl\\anaconda3\\envs\\tf1_env\\lib\\inspect.py\", line 696, in getsourcefile\n",
      "    if getattr(getmodule(object, filename), '__loader__', None) is not None:\n",
      "  File \"C:\\Users\\thecl\\anaconda3\\envs\\tf1_env\\lib\\inspect.py\", line 733, in getmodule\n",
      "    if ismodule(module) and hasattr(module, '__file__'):\n",
      "  File \"C:\\Users\\thecl\\anaconda3\\envs\\tf1_env\\lib\\site-packages\\tensorflow\\__init__.py\", line 50, in __getattr__\n",
      "    module = self._load()\n",
      "  File \"C:\\Users\\thecl\\anaconda3\\envs\\tf1_env\\lib\\site-packages\\tensorflow\\__init__.py\", line 44, in _load\n",
      "    module = _importlib.import_module(self.__name__)\n",
      "  File \"C:\\Users\\thecl\\anaconda3\\envs\\tf1_env\\lib\\importlib\\__init__.py\", line 127, in import_module\n",
      "    return _bootstrap._gcd_import(name[level:], package, level)\n",
      "  File \"<frozen importlib._bootstrap>\", line 1006, in _gcd_import\n",
      "  File \"<frozen importlib._bootstrap>\", line 983, in _find_and_load\n",
      "  File \"<frozen importlib._bootstrap>\", line 953, in _find_and_load_unlocked\n",
      "  File \"<frozen importlib._bootstrap>\", line 219, in _call_with_frames_removed\n",
      "  File \"<frozen importlib._bootstrap>\", line 1006, in _gcd_import\n",
      "  File \"<frozen importlib._bootstrap>\", line 983, in _find_and_load\n",
      "  File \"<frozen importlib._bootstrap>\", line 967, in _find_and_load_unlocked\n",
      "  File \"<frozen importlib._bootstrap>\", line 677, in _load_unlocked\n",
      "  File \"<frozen importlib._bootstrap_external>\", line 728, in exec_module\n",
      "  File \"<frozen importlib._bootstrap>\", line 219, in _call_with_frames_removed\n",
      "  File \"C:\\Users\\thecl\\anaconda3\\envs\\tf1_env\\lib\\site-packages\\tensorflow_core\\__init__.py\", line 33, in <module>\n",
      "    from tensorflow._api.v1 import audio\n",
      "  File \"C:\\Users\\thecl\\anaconda3\\envs\\tf1_env\\lib\\site-packages\\tensorflow_core\\_api\\v1\\audio\\__init__.py\", line 10, in <module>\n",
      "    from tensorflow.python.ops.gen_audio_ops import decode_wav\n",
      "  File \"C:\\Users\\thecl\\anaconda3\\envs\\tf1_env\\lib\\site-packages\\tensorflow_core\\python\\ops\\gen_audio_ops.py\", line 11, in <module>\n",
      "    from tensorflow.python.eager import context as _context\n",
      "  File \"C:\\Users\\thecl\\anaconda3\\envs\\tf1_env\\lib\\site-packages\\tensorflow_core\\python\\eager\\context.py\", line 29, in <module>\n",
      "    from tensorflow.core.protobuf import config_pb2\n",
      "  File \"C:\\Users\\thecl\\anaconda3\\envs\\tf1_env\\lib\\site-packages\\tensorflow_core\\core\\protobuf\\config_pb2.py\", line 16, in <module>\n",
      "    from tensorflow.core.framework import cost_graph_pb2 as tensorflow_dot_core_dot_framework_dot_cost__graph__pb2\n",
      "  File \"C:\\Users\\thecl\\anaconda3\\envs\\tf1_env\\lib\\site-packages\\tensorflow_core\\core\\framework\\cost_graph_pb2.py\", line 16, in <module>\n",
      "    from tensorflow.core.framework import tensor_shape_pb2 as tensorflow_dot_core_dot_framework_dot_tensor__shape__pb2\n",
      "  File \"C:\\Users\\thecl\\anaconda3\\envs\\tf1_env\\lib\\site-packages\\tensorflow_core\\core\\framework\\tensor_shape_pb2.py\", line 42, in <module>\n",
      "    serialized_options=None, file=DESCRIPTOR),\n",
      "  File \"C:\\Users\\thecl\\anaconda3\\envs\\tf1_env\\lib\\site-packages\\google\\protobuf\\descriptor.py\", line 561, in __new__\n",
      "    _message.Message._CheckCalledFromGeneratedFile()\n",
      "TypeError: Descriptors cannot not be created directly.\n",
      "If this call came from a _pb2.py file, your generated code is out of date and must be regenerated with protoc >= 3.19.0.\n",
      "If you cannot immediately regenerate your protos, some other possible workarounds are:\n",
      " 1. Downgrade the protobuf package to 3.20.x or lower.\n",
      " 2. Set PROTOCOL_BUFFERS_PYTHON_IMPLEMENTATION=python (but this will use pure-Python parsing and will be much slower).\n",
      "\n",
      "More information: https://developers.google.com/protocol-buffers/docs/news/2022-05-06#python-updates\n",
      "ERROR! Session/line number was not unique in database. History logging moved to new session 69\n",
      "Traceback (most recent call last):\n",
      "  File \"C:\\Users\\thecl\\anaconda3\\envs\\tf1_env\\lib\\site-packages\\IPython\\core\\interactiveshell.py\", line 3457, in run_code\n",
      "    exec(code_obj, self.user_global_ns, self.user_ns)\n",
      "  File \"C:\\Users\\thecl\\AppData\\Local\\Temp\\ipykernel_21112\\66615791.py\", line 1, in <module>\n",
      "    feat_cols = [image_var, image_skew, image_curt, entropy]\n",
      "NameError: name 'image_var' is not defined\n",
      "\n",
      "During handling of the above exception, another exception occurred:\n",
      "\n",
      "Traceback (most recent call last):\n",
      "  File \"C:\\Users\\thecl\\anaconda3\\envs\\tf1_env\\lib\\site-packages\\IPython\\core\\interactiveshell.py\", line 2077, in showtraceback\n",
      "    stb = value._render_traceback_()\n",
      "AttributeError: 'NameError' object has no attribute '_render_traceback_'\n",
      "\n",
      "During handling of the above exception, another exception occurred:\n",
      "\n",
      "Traceback (most recent call last):\n",
      "  File \"C:\\Users\\thecl\\anaconda3\\envs\\tf1_env\\lib\\site-packages\\IPython\\core\\interactiveshell.py\", line 3377, in run_ast_nodes\n",
      "    if (await self.run_code(code, result,  async_=asy)):\n",
      "  File \"C:\\Users\\thecl\\anaconda3\\envs\\tf1_env\\lib\\site-packages\\IPython\\core\\interactiveshell.py\", line 3474, in run_code\n",
      "    self.showtraceback(running_compiled_code=True)\n",
      "  File \"C:\\Users\\thecl\\anaconda3\\envs\\tf1_env\\lib\\site-packages\\IPython\\core\\interactiveshell.py\", line 2080, in showtraceback\n",
      "    value, tb, tb_offset=tb_offset)\n",
      "  File \"C:\\Users\\thecl\\anaconda3\\envs\\tf1_env\\lib\\site-packages\\IPython\\core\\ultratb.py\", line 1368, in structured_traceback\n",
      "    self, etype, value, tb, tb_offset, number_of_lines_of_context)\n",
      "  File \"C:\\Users\\thecl\\anaconda3\\envs\\tf1_env\\lib\\site-packages\\IPython\\core\\ultratb.py\", line 1268, in structured_traceback\n",
      "    self, etype, value, tb, tb_offset, number_of_lines_of_context\n",
      "  File \"C:\\Users\\thecl\\anaconda3\\envs\\tf1_env\\lib\\site-packages\\IPython\\core\\ultratb.py\", line 1125, in structured_traceback\n",
      "    tb_offset)\n",
      "  File \"C:\\Users\\thecl\\anaconda3\\envs\\tf1_env\\lib\\site-packages\\IPython\\core\\ultratb.py\", line 1082, in format_exception_as_a_whole\n",
      "    last_unique, recursion_repeat = find_recursion(orig_etype, evalue, records)\n",
      "  File \"C:\\Users\\thecl\\anaconda3\\envs\\tf1_env\\lib\\site-packages\\IPython\\core\\ultratb.py\", line 382, in find_recursion\n",
      "    return len(records), 0\n",
      "TypeError: object of type 'NoneType' has no len()\n",
      "\n",
      "During handling of the above exception, another exception occurred:\n",
      "\n",
      "Traceback (most recent call last):\n",
      "  File \"C:\\Users\\thecl\\anaconda3\\envs\\tf1_env\\lib\\site-packages\\IPython\\core\\interactiveshell.py\", line 2077, in showtraceback\n",
      "    stb = value._render_traceback_()\n",
      "AttributeError: 'TypeError' object has no attribute '_render_traceback_'\n",
      "\n",
      "During handling of the above exception, another exception occurred:\n",
      "\n",
      "Traceback (most recent call last):\n",
      "  File \"C:\\Users\\thecl\\anaconda3\\envs\\tf1_env\\lib\\site-packages\\IPython\\core\\ultratb.py\", line 1101, in get_records\n",
      "    return _fixed_getinnerframes(etb, number_of_lines_of_context, tb_offset)\n",
      "  File \"C:\\Users\\thecl\\anaconda3\\envs\\tf1_env\\lib\\site-packages\\IPython\\core\\ultratb.py\", line 248, in wrapped\n",
      "    return f(*args, **kwargs)\n",
      "  File \"C:\\Users\\thecl\\anaconda3\\envs\\tf1_env\\lib\\site-packages\\IPython\\core\\ultratb.py\", line 281, in _fixed_getinnerframes\n",
      "    records = fix_frame_records_filenames(inspect.getinnerframes(etb, context))\n",
      "  File \"C:\\Users\\thecl\\anaconda3\\envs\\tf1_env\\lib\\inspect.py\", line 1500, in getinnerframes\n",
      "    frameinfo = (tb.tb_frame,) + getframeinfo(tb, context)\n",
      "  File \"C:\\Users\\thecl\\anaconda3\\envs\\tf1_env\\lib\\inspect.py\", line 1458, in getframeinfo\n",
      "    filename = getsourcefile(frame) or getfile(frame)\n",
      "  File \"C:\\Users\\thecl\\anaconda3\\envs\\tf1_env\\lib\\inspect.py\", line 696, in getsourcefile\n",
      "    if getattr(getmodule(object, filename), '__loader__', None) is not None:\n",
      "  File \"C:\\Users\\thecl\\anaconda3\\envs\\tf1_env\\lib\\inspect.py\", line 733, in getmodule\n",
      "    if ismodule(module) and hasattr(module, '__file__'):\n",
      "  File \"C:\\Users\\thecl\\anaconda3\\envs\\tf1_env\\lib\\site-packages\\tensorflow\\__init__.py\", line 50, in __getattr__\n",
      "    module = self._load()\n",
      "  File \"C:\\Users\\thecl\\anaconda3\\envs\\tf1_env\\lib\\site-packages\\tensorflow\\__init__.py\", line 44, in _load\n",
      "    module = _importlib.import_module(self.__name__)\n",
      "  File \"C:\\Users\\thecl\\anaconda3\\envs\\tf1_env\\lib\\importlib\\__init__.py\", line 127, in import_module\n",
      "    return _bootstrap._gcd_import(name[level:], package, level)\n",
      "  File \"<frozen importlib._bootstrap>\", line 1006, in _gcd_import\n",
      "  File \"<frozen importlib._bootstrap>\", line 983, in _find_and_load\n",
      "  File \"<frozen importlib._bootstrap>\", line 953, in _find_and_load_unlocked\n",
      "  File \"<frozen importlib._bootstrap>\", line 219, in _call_with_frames_removed\n",
      "  File \"<frozen importlib._bootstrap>\", line 1006, in _gcd_import\n",
      "  File \"<frozen importlib._bootstrap>\", line 983, in _find_and_load\n",
      "  File \"<frozen importlib._bootstrap>\", line 967, in _find_and_load_unlocked\n",
      "  File \"<frozen importlib._bootstrap>\", line 677, in _load_unlocked\n",
      "  File \"<frozen importlib._bootstrap_external>\", line 728, in exec_module\n",
      "  File \"<frozen importlib._bootstrap>\", line 219, in _call_with_frames_removed\n",
      "  File \"C:\\Users\\thecl\\anaconda3\\envs\\tf1_env\\lib\\site-packages\\tensorflow_core\\__init__.py\", line 33, in <module>\n",
      "    from tensorflow._api.v1 import audio\n",
      "  File \"C:\\Users\\thecl\\anaconda3\\envs\\tf1_env\\lib\\site-packages\\tensorflow_core\\_api\\v1\\audio\\__init__.py\", line 10, in <module>\n",
      "    from tensorflow.python.ops.gen_audio_ops import decode_wav\n",
      "  File \"C:\\Users\\thecl\\anaconda3\\envs\\tf1_env\\lib\\site-packages\\tensorflow_core\\python\\ops\\gen_audio_ops.py\", line 11, in <module>\n",
      "    from tensorflow.python.eager import context as _context\n",
      "  File \"C:\\Users\\thecl\\anaconda3\\envs\\tf1_env\\lib\\site-packages\\tensorflow_core\\python\\eager\\context.py\", line 29, in <module>\n",
      "    from tensorflow.core.protobuf import config_pb2\n",
      "  File \"C:\\Users\\thecl\\anaconda3\\envs\\tf1_env\\lib\\site-packages\\tensorflow_core\\core\\protobuf\\config_pb2.py\", line 16, in <module>\n",
      "    from tensorflow.core.framework import cost_graph_pb2 as tensorflow_dot_core_dot_framework_dot_cost__graph__pb2\n",
      "  File \"C:\\Users\\thecl\\anaconda3\\envs\\tf1_env\\lib\\site-packages\\tensorflow_core\\core\\framework\\cost_graph_pb2.py\", line 16, in <module>\n",
      "    from tensorflow.core.framework import tensor_shape_pb2 as tensorflow_dot_core_dot_framework_dot_tensor__shape__pb2\n",
      "  File \"C:\\Users\\thecl\\anaconda3\\envs\\tf1_env\\lib\\site-packages\\tensorflow_core\\core\\framework\\tensor_shape_pb2.py\", line 42, in <module>\n",
      "    serialized_options=None, file=DESCRIPTOR),\n",
      "  File \"C:\\Users\\thecl\\anaconda3\\envs\\tf1_env\\lib\\site-packages\\google\\protobuf\\descriptor.py\", line 561, in __new__\n",
      "    _message.Message._CheckCalledFromGeneratedFile()\n",
      "TypeError: Descriptors cannot not be created directly.\n",
      "If this call came from a _pb2.py file, your generated code is out of date and must be regenerated with protoc >= 3.19.0.\n",
      "If you cannot immediately regenerate your protos, some other possible workarounds are:\n",
      " 1. Downgrade the protobuf package to 3.20.x or lower.\n",
      " 2. Set PROTOCOL_BUFFERS_PYTHON_IMPLEMENTATION=python (but this will use pure-Python parsing and will be much slower).\n",
      "\n",
      "More information: https://developers.google.com/protocol-buffers/docs/news/2022-05-06#python-updates\n",
      "Traceback (most recent call last):\n",
      "  File \"C:\\Users\\thecl\\anaconda3\\envs\\tf1_env\\lib\\site-packages\\IPython\\core\\interactiveshell.py\", line 3457, in run_code\n",
      "    exec(code_obj, self.user_global_ns, self.user_ns)\n",
      "  File \"C:\\Users\\thecl\\AppData\\Local\\Temp\\ipykernel_21112\\66615791.py\", line 1, in <module>\n",
      "    feat_cols = [image_var, image_skew, image_curt, entropy]\n",
      "NameError: name 'image_var' is not defined\n",
      "\n",
      "During handling of the above exception, another exception occurred:\n",
      "\n",
      "Traceback (most recent call last):\n",
      "  File \"C:\\Users\\thecl\\anaconda3\\envs\\tf1_env\\lib\\site-packages\\IPython\\core\\interactiveshell.py\", line 2077, in showtraceback\n",
      "    stb = value._render_traceback_()\n",
      "AttributeError: 'NameError' object has no attribute '_render_traceback_'\n",
      "\n",
      "During handling of the above exception, another exception occurred:\n",
      "\n",
      "Traceback (most recent call last):\n",
      "  File \"C:\\Users\\thecl\\anaconda3\\envs\\tf1_env\\lib\\site-packages\\IPython\\core\\interactiveshell.py\", line 3377, in run_ast_nodes\n",
      "    if (await self.run_code(code, result,  async_=asy)):\n",
      "  File \"C:\\Users\\thecl\\anaconda3\\envs\\tf1_env\\lib\\site-packages\\IPython\\core\\interactiveshell.py\", line 3474, in run_code\n",
      "    self.showtraceback(running_compiled_code=True)\n",
      "  File \"C:\\Users\\thecl\\anaconda3\\envs\\tf1_env\\lib\\site-packages\\IPython\\core\\interactiveshell.py\", line 2080, in showtraceback\n",
      "    value, tb, tb_offset=tb_offset)\n",
      "  File \"C:\\Users\\thecl\\anaconda3\\envs\\tf1_env\\lib\\site-packages\\IPython\\core\\ultratb.py\", line 1368, in structured_traceback\n",
      "    self, etype, value, tb, tb_offset, number_of_lines_of_context)\n",
      "  File \"C:\\Users\\thecl\\anaconda3\\envs\\tf1_env\\lib\\site-packages\\IPython\\core\\ultratb.py\", line 1268, in structured_traceback\n",
      "    self, etype, value, tb, tb_offset, number_of_lines_of_context\n",
      "  File \"C:\\Users\\thecl\\anaconda3\\envs\\tf1_env\\lib\\site-packages\\IPython\\core\\ultratb.py\", line 1125, in structured_traceback\n",
      "    tb_offset)\n",
      "  File \"C:\\Users\\thecl\\anaconda3\\envs\\tf1_env\\lib\\site-packages\\IPython\\core\\ultratb.py\", line 1082, in format_exception_as_a_whole\n",
      "    last_unique, recursion_repeat = find_recursion(orig_etype, evalue, records)\n",
      "  File \"C:\\Users\\thecl\\anaconda3\\envs\\tf1_env\\lib\\site-packages\\IPython\\core\\ultratb.py\", line 382, in find_recursion\n",
      "    return len(records), 0\n",
      "TypeError: object of type 'NoneType' has no len()\n",
      "\n",
      "During handling of the above exception, another exception occurred:\n",
      "\n",
      "Traceback (most recent call last):\n",
      "  File \"C:\\Users\\thecl\\anaconda3\\envs\\tf1_env\\lib\\site-packages\\IPython\\core\\interactiveshell.py\", line 2077, in showtraceback\n",
      "    stb = value._render_traceback_()\n",
      "AttributeError: 'TypeError' object has no attribute '_render_traceback_'\n",
      "\n",
      "During handling of the above exception, another exception occurred:\n",
      "\n",
      "Traceback (most recent call last):\n",
      "  File \"C:\\Users\\thecl\\anaconda3\\envs\\tf1_env\\lib\\site-packages\\IPython\\core\\interactiveshell.py\", line 2960, in _run_cell\n",
      "    return runner(coro)\n",
      "  File \"C:\\Users\\thecl\\anaconda3\\envs\\tf1_env\\lib\\site-packages\\IPython\\core\\async_helpers.py\", line 78, in _pseudo_sync_runner\n",
      "    coro.send(None)\n",
      "  File \"C:\\Users\\thecl\\anaconda3\\envs\\tf1_env\\lib\\site-packages\\IPython\\core\\interactiveshell.py\", line 3186, in run_cell_async\n",
      "    interactivity=interactivity, compiler=compiler, result=result)\n",
      "  File \"C:\\Users\\thecl\\anaconda3\\envs\\tf1_env\\lib\\site-packages\\IPython\\core\\interactiveshell.py\", line 3396, in run_ast_nodes\n",
      "    self.showtraceback()\n",
      "  File \"C:\\Users\\thecl\\anaconda3\\envs\\tf1_env\\lib\\site-packages\\IPython\\core\\interactiveshell.py\", line 2080, in showtraceback\n",
      "    value, tb, tb_offset=tb_offset)\n",
      "  File \"C:\\Users\\thecl\\anaconda3\\envs\\tf1_env\\lib\\site-packages\\IPython\\core\\ultratb.py\", line 1368, in structured_traceback\n",
      "    self, etype, value, tb, tb_offset, number_of_lines_of_context)\n",
      "  File \"C:\\Users\\thecl\\anaconda3\\envs\\tf1_env\\lib\\site-packages\\IPython\\core\\ultratb.py\", line 1268, in structured_traceback\n",
      "    self, etype, value, tb, tb_offset, number_of_lines_of_context\n",
      "  File \"C:\\Users\\thecl\\anaconda3\\envs\\tf1_env\\lib\\site-packages\\IPython\\core\\ultratb.py\", line 1143, in structured_traceback\n",
      "    chained_exceptions_tb_offset)\n",
      "  File \"C:\\Users\\thecl\\anaconda3\\envs\\tf1_env\\lib\\site-packages\\IPython\\core\\ultratb.py\", line 1082, in format_exception_as_a_whole\n",
      "    last_unique, recursion_repeat = find_recursion(orig_etype, evalue, records)\n",
      "  File \"C:\\Users\\thecl\\anaconda3\\envs\\tf1_env\\lib\\site-packages\\IPython\\core\\ultratb.py\", line 382, in find_recursion\n",
      "    return len(records), 0\n",
      "TypeError: object of type 'NoneType' has no len()\n",
      "\n",
      "During handling of the above exception, another exception occurred:\n",
      "\n",
      "Traceback (most recent call last):\n",
      "  File \"C:\\Users\\thecl\\anaconda3\\envs\\tf1_env\\lib\\site-packages\\IPython\\core\\interactiveshell.py\", line 2077, in showtraceback\n",
      "    stb = value._render_traceback_()\n",
      "AttributeError: 'TypeError' object has no attribute '_render_traceback_'\n",
      "\n",
      "During handling of the above exception, another exception occurred:\n",
      "\n",
      "Traceback (most recent call last):\n",
      "  File \"C:\\Users\\thecl\\anaconda3\\envs\\tf1_env\\lib\\site-packages\\IPython\\core\\ultratb.py\", line 1101, in get_records\n",
      "    return _fixed_getinnerframes(etb, number_of_lines_of_context, tb_offset)\n",
      "  File \"C:\\Users\\thecl\\anaconda3\\envs\\tf1_env\\lib\\site-packages\\IPython\\core\\ultratb.py\", line 248, in wrapped\n",
      "    return f(*args, **kwargs)\n",
      "  File \"C:\\Users\\thecl\\anaconda3\\envs\\tf1_env\\lib\\site-packages\\IPython\\core\\ultratb.py\", line 281, in _fixed_getinnerframes\n",
      "    records = fix_frame_records_filenames(inspect.getinnerframes(etb, context))\n",
      "  File \"C:\\Users\\thecl\\anaconda3\\envs\\tf1_env\\lib\\inspect.py\", line 1500, in getinnerframes\n",
      "    frameinfo = (tb.tb_frame,) + getframeinfo(tb, context)\n",
      "  File \"C:\\Users\\thecl\\anaconda3\\envs\\tf1_env\\lib\\inspect.py\", line 1458, in getframeinfo\n",
      "    filename = getsourcefile(frame) or getfile(frame)\n",
      "  File \"C:\\Users\\thecl\\anaconda3\\envs\\tf1_env\\lib\\inspect.py\", line 696, in getsourcefile\n",
      "    if getattr(getmodule(object, filename), '__loader__', None) is not None:\n",
      "  File \"C:\\Users\\thecl\\anaconda3\\envs\\tf1_env\\lib\\inspect.py\", line 733, in getmodule\n",
      "    if ismodule(module) and hasattr(module, '__file__'):\n",
      "  File \"C:\\Users\\thecl\\anaconda3\\envs\\tf1_env\\lib\\site-packages\\tensorflow\\__init__.py\", line 50, in __getattr__\n",
      "    module = self._load()\n",
      "  File \"C:\\Users\\thecl\\anaconda3\\envs\\tf1_env\\lib\\site-packages\\tensorflow\\__init__.py\", line 44, in _load\n",
      "    module = _importlib.import_module(self.__name__)\n",
      "  File \"C:\\Users\\thecl\\anaconda3\\envs\\tf1_env\\lib\\importlib\\__init__.py\", line 127, in import_module\n",
      "    return _bootstrap._gcd_import(name[level:], package, level)\n",
      "  File \"<frozen importlib._bootstrap>\", line 1006, in _gcd_import\n",
      "  File \"<frozen importlib._bootstrap>\", line 983, in _find_and_load\n",
      "  File \"<frozen importlib._bootstrap>\", line 953, in _find_and_load_unlocked\n",
      "  File \"<frozen importlib._bootstrap>\", line 219, in _call_with_frames_removed\n",
      "  File \"<frozen importlib._bootstrap>\", line 1006, in _gcd_import\n",
      "  File \"<frozen importlib._bootstrap>\", line 983, in _find_and_load\n",
      "  File \"<frozen importlib._bootstrap>\", line 967, in _find_and_load_unlocked\n",
      "  File \"<frozen importlib._bootstrap>\", line 677, in _load_unlocked\n",
      "  File \"<frozen importlib._bootstrap_external>\", line 728, in exec_module\n",
      "  File \"<frozen importlib._bootstrap>\", line 219, in _call_with_frames_removed\n",
      "  File \"C:\\Users\\thecl\\anaconda3\\envs\\tf1_env\\lib\\site-packages\\tensorflow_core\\__init__.py\", line 33, in <module>\n",
      "    from tensorflow._api.v1 import audio\n",
      "  File \"C:\\Users\\thecl\\anaconda3\\envs\\tf1_env\\lib\\site-packages\\tensorflow_core\\_api\\v1\\audio\\__init__.py\", line 10, in <module>\n",
      "    from tensorflow.python.ops.gen_audio_ops import decode_wav\n",
      "  File \"C:\\Users\\thecl\\anaconda3\\envs\\tf1_env\\lib\\site-packages\\tensorflow_core\\python\\ops\\gen_audio_ops.py\", line 11, in <module>\n",
      "    from tensorflow.python.eager import context as _context\n",
      "  File \"C:\\Users\\thecl\\anaconda3\\envs\\tf1_env\\lib\\site-packages\\tensorflow_core\\python\\eager\\context.py\", line 29, in <module>\n",
      "    from tensorflow.core.protobuf import config_pb2\n",
      "  File \"C:\\Users\\thecl\\anaconda3\\envs\\tf1_env\\lib\\site-packages\\tensorflow_core\\core\\protobuf\\config_pb2.py\", line 16, in <module>\n",
      "    from tensorflow.core.framework import cost_graph_pb2 as tensorflow_dot_core_dot_framework_dot_cost__graph__pb2\n",
      "  File \"C:\\Users\\thecl\\anaconda3\\envs\\tf1_env\\lib\\site-packages\\tensorflow_core\\core\\framework\\cost_graph_pb2.py\", line 16, in <module>\n",
      "    from tensorflow.core.framework import tensor_shape_pb2 as tensorflow_dot_core_dot_framework_dot_tensor__shape__pb2\n",
      "  File \"C:\\Users\\thecl\\anaconda3\\envs\\tf1_env\\lib\\site-packages\\tensorflow_core\\core\\framework\\tensor_shape_pb2.py\", line 42, in <module>\n",
      "    serialized_options=None, file=DESCRIPTOR),\n",
      "  File \"C:\\Users\\thecl\\anaconda3\\envs\\tf1_env\\lib\\site-packages\\google\\protobuf\\descriptor.py\", line 561, in __new__\n",
      "    _message.Message._CheckCalledFromGeneratedFile()\n",
      "TypeError: Descriptors cannot not be created directly.\n",
      "If this call came from a _pb2.py file, your generated code is out of date and must be regenerated with protoc >= 3.19.0.\n",
      "If you cannot immediately regenerate your protos, some other possible workarounds are:\n",
      " 1. Downgrade the protobuf package to 3.20.x or lower.\n",
      " 2. Set PROTOCOL_BUFFERS_PYTHON_IMPLEMENTATION=python (but this will use pure-Python parsing and will be much slower).\n",
      "\n",
      "More information: https://developers.google.com/protocol-buffers/docs/news/2022-05-06#python-updates\n"
     ]
    }
   ],
   "source": [
    "feat_cols = [image_var, image_skew, image_curt, entropy]"
   ]
  },
  {
   "cell_type": "markdown",
   "metadata": {},
   "source": [
    "# Tensorflow"
   ]
  },
  {
   "cell_type": "code",
   "execution_count": null,
   "metadata": {},
   "outputs": [],
   "source": []
  },
  {
   "cell_type": "markdown",
   "metadata": {},
   "source": [
    "** Create a list of feature column objects using tf.feature.numeric_column() as we did in the lecture**"
   ]
  },
  {
   "cell_type": "code",
   "execution_count": null,
   "metadata": {},
   "outputs": [],
   "source": []
  },
  {
   "cell_type": "code",
   "execution_count": null,
   "metadata": {},
   "outputs": [
    {
     "name": "stderr",
     "output_type": "stream",
     "text": [
      "ERROR:root:Internal Python error in the inspect module.\n",
      "Below is the traceback from this internal error.\n",
      "\n",
      "ERROR:root:Internal Python error in the inspect module.\n",
      "Below is the traceback from this internal error.\n",
      "\n"
     ]
    },
    {
     "name": "stdout",
     "output_type": "stream",
     "text": [
      "ERROR! Session/line number was not unique in database. History logging moved to new session 70\n",
      "Traceback (most recent call last):\n",
      "  File \"C:\\Users\\thecl\\anaconda3\\envs\\tf1_env\\lib\\site-packages\\IPython\\core\\interactiveshell.py\", line 3457, in run_code\n",
      "    exec(code_obj, self.user_global_ns, self.user_ns)\n",
      "  File \"C:\\Users\\thecl\\AppData\\Local\\Temp\\ipykernel_21112\\1353248311.py\", line 3, in <module>\n",
      "    import tensorflow_estimator as tfe\n",
      "  File \"C:\\Users\\thecl\\anaconda3\\envs\\tf1_env\\lib\\site-packages\\tensorflow_estimator\\__init__.py\", line 10, in <module>\n",
      "    from tensorflow_estimator._api.v1 import estimator\n",
      "  File \"C:\\Users\\thecl\\anaconda3\\envs\\tf1_env\\lib\\site-packages\\tensorflow_estimator\\_api\\v1\\estimator\\__init__.py\", line 10, in <module>\n",
      "    from tensorflow_estimator._api.v1.estimator import experimental\n",
      "  File \"C:\\Users\\thecl\\anaconda3\\envs\\tf1_env\\lib\\site-packages\\tensorflow_estimator\\_api\\v1\\estimator\\experimental\\__init__.py\", line 10, in <module>\n",
      "    from tensorflow_estimator.python.estimator.canned.dnn import dnn_logit_fn_builder\n",
      "  File \"C:\\Users\\thecl\\anaconda3\\envs\\tf1_env\\lib\\site-packages\\tensorflow_estimator\\python\\estimator\\canned\\dnn.py\", line 23, in <module>\n",
      "    from tensorflow.python.feature_column import dense_features\n",
      "  File \"C:\\Users\\thecl\\anaconda3\\envs\\tf1_env\\lib\\site-packages\\tensorflow_core\\python\\feature_column\\dense_features.py\", line 23, in <module>\n",
      "    from tensorflow.python.feature_column import feature_column_v2 as fc\n",
      "  File \"C:\\Users\\thecl\\anaconda3\\envs\\tf1_env\\lib\\site-packages\\tensorflow_core\\python\\feature_column\\feature_column_v2.py\", line 138, in <module>\n",
      "    from tensorflow.python.eager import context\n",
      "  File \"C:\\Users\\thecl\\anaconda3\\envs\\tf1_env\\lib\\site-packages\\tensorflow_core\\python\\eager\\context.py\", line 29, in <module>\n",
      "    from tensorflow.core.protobuf import config_pb2\n",
      "  File \"C:\\Users\\thecl\\anaconda3\\envs\\tf1_env\\lib\\site-packages\\tensorflow_core\\core\\protobuf\\config_pb2.py\", line 16, in <module>\n",
      "    from tensorflow.core.framework import cost_graph_pb2 as tensorflow_dot_core_dot_framework_dot_cost__graph__pb2\n",
      "  File \"C:\\Users\\thecl\\anaconda3\\envs\\tf1_env\\lib\\site-packages\\tensorflow_core\\core\\framework\\cost_graph_pb2.py\", line 16, in <module>\n",
      "    from tensorflow.core.framework import tensor_shape_pb2 as tensorflow_dot_core_dot_framework_dot_tensor__shape__pb2\n",
      "  File \"C:\\Users\\thecl\\anaconda3\\envs\\tf1_env\\lib\\site-packages\\tensorflow_core\\core\\framework\\tensor_shape_pb2.py\", line 42, in <module>\n",
      "    serialized_options=None, file=DESCRIPTOR),\n",
      "  File \"C:\\Users\\thecl\\anaconda3\\envs\\tf1_env\\lib\\site-packages\\google\\protobuf\\descriptor.py\", line 561, in __new__\n",
      "    _message.Message._CheckCalledFromGeneratedFile()\n",
      "TypeError: Descriptors cannot not be created directly.\n",
      "If this call came from a _pb2.py file, your generated code is out of date and must be regenerated with protoc >= 3.19.0.\n",
      "If you cannot immediately regenerate your protos, some other possible workarounds are:\n",
      " 1. Downgrade the protobuf package to 3.20.x or lower.\n",
      " 2. Set PROTOCOL_BUFFERS_PYTHON_IMPLEMENTATION=python (but this will use pure-Python parsing and will be much slower).\n",
      "\n",
      "More information: https://developers.google.com/protocol-buffers/docs/news/2022-05-06#python-updates\n",
      "\n",
      "During handling of the above exception, another exception occurred:\n",
      "\n",
      "Traceback (most recent call last):\n",
      "  File \"C:\\Users\\thecl\\anaconda3\\envs\\tf1_env\\lib\\site-packages\\IPython\\core\\interactiveshell.py\", line 2077, in showtraceback\n",
      "    stb = value._render_traceback_()\n",
      "AttributeError: 'TypeError' object has no attribute '_render_traceback_'\n",
      "\n",
      "During handling of the above exception, another exception occurred:\n",
      "\n",
      "Traceback (most recent call last):\n",
      "  File \"C:\\Users\\thecl\\anaconda3\\envs\\tf1_env\\lib\\site-packages\\IPython\\core\\ultratb.py\", line 1101, in get_records\n",
      "    return _fixed_getinnerframes(etb, number_of_lines_of_context, tb_offset)\n",
      "  File \"C:\\Users\\thecl\\anaconda3\\envs\\tf1_env\\lib\\site-packages\\IPython\\core\\ultratb.py\", line 248, in wrapped\n",
      "    return f(*args, **kwargs)\n",
      "  File \"C:\\Users\\thecl\\anaconda3\\envs\\tf1_env\\lib\\site-packages\\IPython\\core\\ultratb.py\", line 281, in _fixed_getinnerframes\n",
      "    records = fix_frame_records_filenames(inspect.getinnerframes(etb, context))\n",
      "  File \"C:\\Users\\thecl\\anaconda3\\envs\\tf1_env\\lib\\inspect.py\", line 1500, in getinnerframes\n",
      "    frameinfo = (tb.tb_frame,) + getframeinfo(tb, context)\n",
      "  File \"C:\\Users\\thecl\\anaconda3\\envs\\tf1_env\\lib\\inspect.py\", line 1458, in getframeinfo\n",
      "    filename = getsourcefile(frame) or getfile(frame)\n",
      "  File \"C:\\Users\\thecl\\anaconda3\\envs\\tf1_env\\lib\\inspect.py\", line 696, in getsourcefile\n",
      "    if getattr(getmodule(object, filename), '__loader__', None) is not None:\n",
      "  File \"C:\\Users\\thecl\\anaconda3\\envs\\tf1_env\\lib\\inspect.py\", line 733, in getmodule\n",
      "    if ismodule(module) and hasattr(module, '__file__'):\n",
      "  File \"C:\\Users\\thecl\\anaconda3\\envs\\tf1_env\\lib\\site-packages\\tensorflow\\__init__.py\", line 50, in __getattr__\n",
      "    module = self._load()\n",
      "  File \"C:\\Users\\thecl\\anaconda3\\envs\\tf1_env\\lib\\site-packages\\tensorflow\\__init__.py\", line 44, in _load\n",
      "    module = _importlib.import_module(self.__name__)\n",
      "  File \"C:\\Users\\thecl\\anaconda3\\envs\\tf1_env\\lib\\importlib\\__init__.py\", line 127, in import_module\n",
      "    return _bootstrap._gcd_import(name[level:], package, level)\n",
      "  File \"<frozen importlib._bootstrap>\", line 1006, in _gcd_import\n",
      "  File \"<frozen importlib._bootstrap>\", line 983, in _find_and_load\n",
      "  File \"<frozen importlib._bootstrap>\", line 953, in _find_and_load_unlocked\n",
      "  File \"<frozen importlib._bootstrap>\", line 219, in _call_with_frames_removed\n",
      "  File \"<frozen importlib._bootstrap>\", line 1006, in _gcd_import\n",
      "  File \"<frozen importlib._bootstrap>\", line 983, in _find_and_load\n",
      "  File \"<frozen importlib._bootstrap>\", line 967, in _find_and_load_unlocked\n",
      "  File \"<frozen importlib._bootstrap>\", line 677, in _load_unlocked\n",
      "  File \"<frozen importlib._bootstrap_external>\", line 728, in exec_module\n",
      "  File \"<frozen importlib._bootstrap>\", line 219, in _call_with_frames_removed\n",
      "  File \"C:\\Users\\thecl\\anaconda3\\envs\\tf1_env\\lib\\site-packages\\tensorflow_core\\__init__.py\", line 33, in <module>\n",
      "    from tensorflow._api.v1 import audio\n",
      "  File \"C:\\Users\\thecl\\anaconda3\\envs\\tf1_env\\lib\\site-packages\\tensorflow_core\\_api\\v1\\audio\\__init__.py\", line 10, in <module>\n",
      "    from tensorflow.python.ops.gen_audio_ops import decode_wav\n",
      "  File \"C:\\Users\\thecl\\anaconda3\\envs\\tf1_env\\lib\\site-packages\\tensorflow_core\\python\\ops\\gen_audio_ops.py\", line 11, in <module>\n",
      "    from tensorflow.python.eager import context as _context\n",
      "  File \"C:\\Users\\thecl\\anaconda3\\envs\\tf1_env\\lib\\site-packages\\tensorflow_core\\python\\eager\\context.py\", line 29, in <module>\n",
      "    from tensorflow.core.protobuf import config_pb2\n",
      "  File \"C:\\Users\\thecl\\anaconda3\\envs\\tf1_env\\lib\\site-packages\\tensorflow_core\\core\\protobuf\\config_pb2.py\", line 16, in <module>\n",
      "    from tensorflow.core.framework import cost_graph_pb2 as tensorflow_dot_core_dot_framework_dot_cost__graph__pb2\n",
      "  File \"C:\\Users\\thecl\\anaconda3\\envs\\tf1_env\\lib\\site-packages\\tensorflow_core\\core\\framework\\cost_graph_pb2.py\", line 16, in <module>\n",
      "    from tensorflow.core.framework import tensor_shape_pb2 as tensorflow_dot_core_dot_framework_dot_tensor__shape__pb2\n",
      "  File \"C:\\Users\\thecl\\anaconda3\\envs\\tf1_env\\lib\\site-packages\\tensorflow_core\\core\\framework\\tensor_shape_pb2.py\", line 42, in <module>\n",
      "    serialized_options=None, file=DESCRIPTOR),\n",
      "  File \"C:\\Users\\thecl\\anaconda3\\envs\\tf1_env\\lib\\site-packages\\google\\protobuf\\descriptor.py\", line 561, in __new__\n",
      "    _message.Message._CheckCalledFromGeneratedFile()\n",
      "TypeError: Descriptors cannot not be created directly.\n",
      "If this call came from a _pb2.py file, your generated code is out of date and must be regenerated with protoc >= 3.19.0.\n",
      "If you cannot immediately regenerate your protos, some other possible workarounds are:\n",
      " 1. Downgrade the protobuf package to 3.20.x or lower.\n",
      " 2. Set PROTOCOL_BUFFERS_PYTHON_IMPLEMENTATION=python (but this will use pure-Python parsing and will be much slower).\n",
      "\n",
      "More information: https://developers.google.com/protocol-buffers/docs/news/2022-05-06#python-updates\n"
     ]
    },
    {
     "name": "stderr",
     "output_type": "stream",
     "text": [
      "ERROR:root:Internal Python error in the inspect module.\n",
      "Below is the traceback from this internal error.\n",
      "\n"
     ]
    },
    {
     "name": "stdout",
     "output_type": "stream",
     "text": [
      "Traceback (most recent call last):\n",
      "  File \"C:\\Users\\thecl\\anaconda3\\envs\\tf1_env\\lib\\site-packages\\IPython\\core\\interactiveshell.py\", line 3457, in run_code\n",
      "    exec(code_obj, self.user_global_ns, self.user_ns)\n",
      "  File \"C:\\Users\\thecl\\AppData\\Local\\Temp\\ipykernel_21112\\1353248311.py\", line 3, in <module>\n",
      "    import tensorflow_estimator as tfe\n",
      "  File \"C:\\Users\\thecl\\anaconda3\\envs\\tf1_env\\lib\\site-packages\\tensorflow_estimator\\__init__.py\", line 10, in <module>\n",
      "    from tensorflow_estimator._api.v1 import estimator\n",
      "  File \"C:\\Users\\thecl\\anaconda3\\envs\\tf1_env\\lib\\site-packages\\tensorflow_estimator\\_api\\v1\\estimator\\__init__.py\", line 10, in <module>\n",
      "    from tensorflow_estimator._api.v1.estimator import experimental\n",
      "  File \"C:\\Users\\thecl\\anaconda3\\envs\\tf1_env\\lib\\site-packages\\tensorflow_estimator\\_api\\v1\\estimator\\experimental\\__init__.py\", line 10, in <module>\n",
      "    from tensorflow_estimator.python.estimator.canned.dnn import dnn_logit_fn_builder\n",
      "  File \"C:\\Users\\thecl\\anaconda3\\envs\\tf1_env\\lib\\site-packages\\tensorflow_estimator\\python\\estimator\\canned\\dnn.py\", line 23, in <module>\n",
      "    from tensorflow.python.feature_column import dense_features\n",
      "  File \"C:\\Users\\thecl\\anaconda3\\envs\\tf1_env\\lib\\site-packages\\tensorflow_core\\python\\feature_column\\dense_features.py\", line 23, in <module>\n",
      "    from tensorflow.python.feature_column import feature_column_v2 as fc\n",
      "  File \"C:\\Users\\thecl\\anaconda3\\envs\\tf1_env\\lib\\site-packages\\tensorflow_core\\python\\feature_column\\feature_column_v2.py\", line 138, in <module>\n",
      "    from tensorflow.python.eager import context\n",
      "  File \"C:\\Users\\thecl\\anaconda3\\envs\\tf1_env\\lib\\site-packages\\tensorflow_core\\python\\eager\\context.py\", line 29, in <module>\n",
      "    from tensorflow.core.protobuf import config_pb2\n",
      "  File \"C:\\Users\\thecl\\anaconda3\\envs\\tf1_env\\lib\\site-packages\\tensorflow_core\\core\\protobuf\\config_pb2.py\", line 16, in <module>\n",
      "    from tensorflow.core.framework import cost_graph_pb2 as tensorflow_dot_core_dot_framework_dot_cost__graph__pb2\n",
      "  File \"C:\\Users\\thecl\\anaconda3\\envs\\tf1_env\\lib\\site-packages\\tensorflow_core\\core\\framework\\cost_graph_pb2.py\", line 16, in <module>\n",
      "    from tensorflow.core.framework import tensor_shape_pb2 as tensorflow_dot_core_dot_framework_dot_tensor__shape__pb2\n",
      "  File \"C:\\Users\\thecl\\anaconda3\\envs\\tf1_env\\lib\\site-packages\\tensorflow_core\\core\\framework\\tensor_shape_pb2.py\", line 42, in <module>\n",
      "    serialized_options=None, file=DESCRIPTOR),\n",
      "  File \"C:\\Users\\thecl\\anaconda3\\envs\\tf1_env\\lib\\site-packages\\google\\protobuf\\descriptor.py\", line 561, in __new__\n",
      "    _message.Message._CheckCalledFromGeneratedFile()\n",
      "TypeError: Descriptors cannot not be created directly.\n",
      "If this call came from a _pb2.py file, your generated code is out of date and must be regenerated with protoc >= 3.19.0.\n",
      "If you cannot immediately regenerate your protos, some other possible workarounds are:\n",
      " 1. Downgrade the protobuf package to 3.20.x or lower.\n",
      " 2. Set PROTOCOL_BUFFERS_PYTHON_IMPLEMENTATION=python (but this will use pure-Python parsing and will be much slower).\n",
      "\n",
      "More information: https://developers.google.com/protocol-buffers/docs/news/2022-05-06#python-updates\n",
      "\n",
      "During handling of the above exception, another exception occurred:\n",
      "\n",
      "Traceback (most recent call last):\n",
      "  File \"C:\\Users\\thecl\\anaconda3\\envs\\tf1_env\\lib\\site-packages\\IPython\\core\\interactiveshell.py\", line 2077, in showtraceback\n",
      "    stb = value._render_traceback_()\n",
      "AttributeError: 'TypeError' object has no attribute '_render_traceback_'\n",
      "\n",
      "During handling of the above exception, another exception occurred:\n",
      "\n",
      "Traceback (most recent call last):\n",
      "  File \"C:\\Users\\thecl\\anaconda3\\envs\\tf1_env\\lib\\site-packages\\IPython\\core\\interactiveshell.py\", line 3377, in run_ast_nodes\n",
      "    if (await self.run_code(code, result,  async_=asy)):\n",
      "  File \"C:\\Users\\thecl\\anaconda3\\envs\\tf1_env\\lib\\site-packages\\IPython\\core\\interactiveshell.py\", line 3474, in run_code\n",
      "    self.showtraceback(running_compiled_code=True)\n",
      "  File \"C:\\Users\\thecl\\anaconda3\\envs\\tf1_env\\lib\\site-packages\\IPython\\core\\interactiveshell.py\", line 2080, in showtraceback\n",
      "    value, tb, tb_offset=tb_offset)\n",
      "  File \"C:\\Users\\thecl\\anaconda3\\envs\\tf1_env\\lib\\site-packages\\IPython\\core\\ultratb.py\", line 1368, in structured_traceback\n",
      "    self, etype, value, tb, tb_offset, number_of_lines_of_context)\n",
      "  File \"C:\\Users\\thecl\\anaconda3\\envs\\tf1_env\\lib\\site-packages\\IPython\\core\\ultratb.py\", line 1268, in structured_traceback\n",
      "    self, etype, value, tb, tb_offset, number_of_lines_of_context\n",
      "  File \"C:\\Users\\thecl\\anaconda3\\envs\\tf1_env\\lib\\site-packages\\IPython\\core\\ultratb.py\", line 1125, in structured_traceback\n",
      "    tb_offset)\n",
      "  File \"C:\\Users\\thecl\\anaconda3\\envs\\tf1_env\\lib\\site-packages\\IPython\\core\\ultratb.py\", line 1082, in format_exception_as_a_whole\n",
      "    last_unique, recursion_repeat = find_recursion(orig_etype, evalue, records)\n",
      "  File \"C:\\Users\\thecl\\anaconda3\\envs\\tf1_env\\lib\\site-packages\\IPython\\core\\ultratb.py\", line 382, in find_recursion\n",
      "    return len(records), 0\n",
      "TypeError: object of type 'NoneType' has no len()\n",
      "\n",
      "During handling of the above exception, another exception occurred:\n",
      "\n",
      "Traceback (most recent call last):\n",
      "  File \"C:\\Users\\thecl\\anaconda3\\envs\\tf1_env\\lib\\site-packages\\IPython\\core\\interactiveshell.py\", line 2077, in showtraceback\n",
      "    stb = value._render_traceback_()\n",
      "AttributeError: 'TypeError' object has no attribute '_render_traceback_'\n",
      "\n",
      "During handling of the above exception, another exception occurred:\n",
      "\n",
      "Traceback (most recent call last):\n",
      "  File \"C:\\Users\\thecl\\anaconda3\\envs\\tf1_env\\lib\\site-packages\\IPython\\core\\ultratb.py\", line 1101, in get_records\n",
      "    return _fixed_getinnerframes(etb, number_of_lines_of_context, tb_offset)\n",
      "  File \"C:\\Users\\thecl\\anaconda3\\envs\\tf1_env\\lib\\site-packages\\IPython\\core\\ultratb.py\", line 248, in wrapped\n",
      "    return f(*args, **kwargs)\n",
      "  File \"C:\\Users\\thecl\\anaconda3\\envs\\tf1_env\\lib\\site-packages\\IPython\\core\\ultratb.py\", line 281, in _fixed_getinnerframes\n",
      "    records = fix_frame_records_filenames(inspect.getinnerframes(etb, context))\n",
      "  File \"C:\\Users\\thecl\\anaconda3\\envs\\tf1_env\\lib\\inspect.py\", line 1500, in getinnerframes\n",
      "    frameinfo = (tb.tb_frame,) + getframeinfo(tb, context)\n",
      "  File \"C:\\Users\\thecl\\anaconda3\\envs\\tf1_env\\lib\\inspect.py\", line 1458, in getframeinfo\n",
      "    filename = getsourcefile(frame) or getfile(frame)\n",
      "  File \"C:\\Users\\thecl\\anaconda3\\envs\\tf1_env\\lib\\inspect.py\", line 696, in getsourcefile\n",
      "    if getattr(getmodule(object, filename), '__loader__', None) is not None:\n",
      "  File \"C:\\Users\\thecl\\anaconda3\\envs\\tf1_env\\lib\\inspect.py\", line 733, in getmodule\n",
      "    if ismodule(module) and hasattr(module, '__file__'):\n",
      "  File \"C:\\Users\\thecl\\anaconda3\\envs\\tf1_env\\lib\\site-packages\\tensorflow\\__init__.py\", line 50, in __getattr__\n",
      "    module = self._load()\n",
      "  File \"C:\\Users\\thecl\\anaconda3\\envs\\tf1_env\\lib\\site-packages\\tensorflow\\__init__.py\", line 44, in _load\n",
      "    module = _importlib.import_module(self.__name__)\n",
      "  File \"C:\\Users\\thecl\\anaconda3\\envs\\tf1_env\\lib\\importlib\\__init__.py\", line 127, in import_module\n",
      "    return _bootstrap._gcd_import(name[level:], package, level)\n",
      "  File \"<frozen importlib._bootstrap>\", line 1006, in _gcd_import\n",
      "  File \"<frozen importlib._bootstrap>\", line 983, in _find_and_load\n",
      "  File \"<frozen importlib._bootstrap>\", line 953, in _find_and_load_unlocked\n",
      "  File \"<frozen importlib._bootstrap>\", line 219, in _call_with_frames_removed\n",
      "  File \"<frozen importlib._bootstrap>\", line 1006, in _gcd_import\n",
      "  File \"<frozen importlib._bootstrap>\", line 983, in _find_and_load\n",
      "  File \"<frozen importlib._bootstrap>\", line 967, in _find_and_load_unlocked\n",
      "  File \"<frozen importlib._bootstrap>\", line 677, in _load_unlocked\n",
      "  File \"<frozen importlib._bootstrap_external>\", line 728, in exec_module\n",
      "  File \"<frozen importlib._bootstrap>\", line 219, in _call_with_frames_removed\n",
      "  File \"C:\\Users\\thecl\\anaconda3\\envs\\tf1_env\\lib\\site-packages\\tensorflow_core\\__init__.py\", line 33, in <module>\n",
      "    from tensorflow._api.v1 import audio\n",
      "  File \"C:\\Users\\thecl\\anaconda3\\envs\\tf1_env\\lib\\site-packages\\tensorflow_core\\_api\\v1\\audio\\__init__.py\", line 10, in <module>\n",
      "    from tensorflow.python.ops.gen_audio_ops import decode_wav\n",
      "  File \"C:\\Users\\thecl\\anaconda3\\envs\\tf1_env\\lib\\site-packages\\tensorflow_core\\python\\ops\\gen_audio_ops.py\", line 11, in <module>\n",
      "    from tensorflow.python.eager import context as _context\n",
      "  File \"C:\\Users\\thecl\\anaconda3\\envs\\tf1_env\\lib\\site-packages\\tensorflow_core\\python\\eager\\context.py\", line 29, in <module>\n",
      "    from tensorflow.core.protobuf import config_pb2\n",
      "  File \"C:\\Users\\thecl\\anaconda3\\envs\\tf1_env\\lib\\site-packages\\tensorflow_core\\core\\protobuf\\config_pb2.py\", line 16, in <module>\n",
      "    from tensorflow.core.framework import cost_graph_pb2 as tensorflow_dot_core_dot_framework_dot_cost__graph__pb2\n",
      "  File \"C:\\Users\\thecl\\anaconda3\\envs\\tf1_env\\lib\\site-packages\\tensorflow_core\\core\\framework\\cost_graph_pb2.py\", line 16, in <module>\n",
      "    from tensorflow.core.framework import tensor_shape_pb2 as tensorflow_dot_core_dot_framework_dot_tensor__shape__pb2\n",
      "  File \"C:\\Users\\thecl\\anaconda3\\envs\\tf1_env\\lib\\site-packages\\tensorflow_core\\core\\framework\\tensor_shape_pb2.py\", line 42, in <module>\n",
      "    serialized_options=None, file=DESCRIPTOR),\n",
      "  File \"C:\\Users\\thecl\\anaconda3\\envs\\tf1_env\\lib\\site-packages\\google\\protobuf\\descriptor.py\", line 561, in __new__\n",
      "    _message.Message._CheckCalledFromGeneratedFile()\n",
      "TypeError: Descriptors cannot not be created directly.\n",
      "If this call came from a _pb2.py file, your generated code is out of date and must be regenerated with protoc >= 3.19.0.\n",
      "If you cannot immediately regenerate your protos, some other possible workarounds are:\n",
      " 1. Downgrade the protobuf package to 3.20.x or lower.\n",
      " 2. Set PROTOCOL_BUFFERS_PYTHON_IMPLEMENTATION=python (but this will use pure-Python parsing and will be much slower).\n",
      "\n",
      "More information: https://developers.google.com/protocol-buffers/docs/news/2022-05-06#python-updates\n",
      "Traceback (most recent call last):\n",
      "  File \"C:\\Users\\thecl\\anaconda3\\envs\\tf1_env\\lib\\site-packages\\IPython\\core\\interactiveshell.py\", line 3457, in run_code\n",
      "    exec(code_obj, self.user_global_ns, self.user_ns)\n",
      "  File \"C:\\Users\\thecl\\AppData\\Local\\Temp\\ipykernel_21112\\1353248311.py\", line 3, in <module>\n",
      "    import tensorflow_estimator as tfe\n",
      "  File \"C:\\Users\\thecl\\anaconda3\\envs\\tf1_env\\lib\\site-packages\\tensorflow_estimator\\__init__.py\", line 10, in <module>\n",
      "    from tensorflow_estimator._api.v1 import estimator\n",
      "  File \"C:\\Users\\thecl\\anaconda3\\envs\\tf1_env\\lib\\site-packages\\tensorflow_estimator\\_api\\v1\\estimator\\__init__.py\", line 10, in <module>\n",
      "    from tensorflow_estimator._api.v1.estimator import experimental\n",
      "  File \"C:\\Users\\thecl\\anaconda3\\envs\\tf1_env\\lib\\site-packages\\tensorflow_estimator\\_api\\v1\\estimator\\experimental\\__init__.py\", line 10, in <module>\n",
      "    from tensorflow_estimator.python.estimator.canned.dnn import dnn_logit_fn_builder\n",
      "  File \"C:\\Users\\thecl\\anaconda3\\envs\\tf1_env\\lib\\site-packages\\tensorflow_estimator\\python\\estimator\\canned\\dnn.py\", line 23, in <module>\n",
      "    from tensorflow.python.feature_column import dense_features\n",
      "  File \"C:\\Users\\thecl\\anaconda3\\envs\\tf1_env\\lib\\site-packages\\tensorflow_core\\python\\feature_column\\dense_features.py\", line 23, in <module>\n",
      "    from tensorflow.python.feature_column import feature_column_v2 as fc\n",
      "  File \"C:\\Users\\thecl\\anaconda3\\envs\\tf1_env\\lib\\site-packages\\tensorflow_core\\python\\feature_column\\feature_column_v2.py\", line 138, in <module>\n",
      "    from tensorflow.python.eager import context\n",
      "  File \"C:\\Users\\thecl\\anaconda3\\envs\\tf1_env\\lib\\site-packages\\tensorflow_core\\python\\eager\\context.py\", line 29, in <module>\n",
      "    from tensorflow.core.protobuf import config_pb2\n",
      "  File \"C:\\Users\\thecl\\anaconda3\\envs\\tf1_env\\lib\\site-packages\\tensorflow_core\\core\\protobuf\\config_pb2.py\", line 16, in <module>\n",
      "    from tensorflow.core.framework import cost_graph_pb2 as tensorflow_dot_core_dot_framework_dot_cost__graph__pb2\n",
      "  File \"C:\\Users\\thecl\\anaconda3\\envs\\tf1_env\\lib\\site-packages\\tensorflow_core\\core\\framework\\cost_graph_pb2.py\", line 16, in <module>\n",
      "    from tensorflow.core.framework import tensor_shape_pb2 as tensorflow_dot_core_dot_framework_dot_tensor__shape__pb2\n",
      "  File \"C:\\Users\\thecl\\anaconda3\\envs\\tf1_env\\lib\\site-packages\\tensorflow_core\\core\\framework\\tensor_shape_pb2.py\", line 42, in <module>\n",
      "    serialized_options=None, file=DESCRIPTOR),\n",
      "  File \"C:\\Users\\thecl\\anaconda3\\envs\\tf1_env\\lib\\site-packages\\google\\protobuf\\descriptor.py\", line 561, in __new__\n",
      "    _message.Message._CheckCalledFromGeneratedFile()\n",
      "TypeError: Descriptors cannot not be created directly.\n",
      "If this call came from a _pb2.py file, your generated code is out of date and must be regenerated with protoc >= 3.19.0.\n",
      "If you cannot immediately regenerate your protos, some other possible workarounds are:\n",
      " 1. Downgrade the protobuf package to 3.20.x or lower.\n",
      " 2. Set PROTOCOL_BUFFERS_PYTHON_IMPLEMENTATION=python (but this will use pure-Python parsing and will be much slower).\n",
      "\n",
      "More information: https://developers.google.com/protocol-buffers/docs/news/2022-05-06#python-updates\n",
      "\n",
      "During handling of the above exception, another exception occurred:\n",
      "\n",
      "Traceback (most recent call last):\n",
      "  File \"C:\\Users\\thecl\\anaconda3\\envs\\tf1_env\\lib\\site-packages\\IPython\\core\\interactiveshell.py\", line 2077, in showtraceback\n",
      "    stb = value._render_traceback_()\n",
      "AttributeError: 'TypeError' object has no attribute '_render_traceback_'\n",
      "\n",
      "During handling of the above exception, another exception occurred:\n",
      "\n",
      "Traceback (most recent call last):\n",
      "  File \"C:\\Users\\thecl\\anaconda3\\envs\\tf1_env\\lib\\site-packages\\IPython\\core\\interactiveshell.py\", line 3377, in run_ast_nodes\n",
      "    if (await self.run_code(code, result,  async_=asy)):\n",
      "  File \"C:\\Users\\thecl\\anaconda3\\envs\\tf1_env\\lib\\site-packages\\IPython\\core\\interactiveshell.py\", line 3474, in run_code\n",
      "    self.showtraceback(running_compiled_code=True)\n",
      "  File \"C:\\Users\\thecl\\anaconda3\\envs\\tf1_env\\lib\\site-packages\\IPython\\core\\interactiveshell.py\", line 2080, in showtraceback\n",
      "    value, tb, tb_offset=tb_offset)\n",
      "  File \"C:\\Users\\thecl\\anaconda3\\envs\\tf1_env\\lib\\site-packages\\IPython\\core\\ultratb.py\", line 1368, in structured_traceback\n",
      "    self, etype, value, tb, tb_offset, number_of_lines_of_context)\n",
      "  File \"C:\\Users\\thecl\\anaconda3\\envs\\tf1_env\\lib\\site-packages\\IPython\\core\\ultratb.py\", line 1268, in structured_traceback\n",
      "    self, etype, value, tb, tb_offset, number_of_lines_of_context\n",
      "  File \"C:\\Users\\thecl\\anaconda3\\envs\\tf1_env\\lib\\site-packages\\IPython\\core\\ultratb.py\", line 1125, in structured_traceback\n",
      "    tb_offset)\n",
      "  File \"C:\\Users\\thecl\\anaconda3\\envs\\tf1_env\\lib\\site-packages\\IPython\\core\\ultratb.py\", line 1082, in format_exception_as_a_whole\n",
      "    last_unique, recursion_repeat = find_recursion(orig_etype, evalue, records)\n",
      "  File \"C:\\Users\\thecl\\anaconda3\\envs\\tf1_env\\lib\\site-packages\\IPython\\core\\ultratb.py\", line 382, in find_recursion\n",
      "    return len(records), 0\n",
      "TypeError: object of type 'NoneType' has no len()\n",
      "\n",
      "During handling of the above exception, another exception occurred:\n",
      "\n",
      "Traceback (most recent call last):\n",
      "  File \"C:\\Users\\thecl\\anaconda3\\envs\\tf1_env\\lib\\site-packages\\IPython\\core\\interactiveshell.py\", line 2077, in showtraceback\n",
      "    stb = value._render_traceback_()\n",
      "AttributeError: 'TypeError' object has no attribute '_render_traceback_'\n",
      "\n",
      "During handling of the above exception, another exception occurred:\n",
      "\n",
      "Traceback (most recent call last):\n",
      "  File \"C:\\Users\\thecl\\anaconda3\\envs\\tf1_env\\lib\\site-packages\\IPython\\core\\interactiveshell.py\", line 2960, in _run_cell\n",
      "    return runner(coro)\n",
      "  File \"C:\\Users\\thecl\\anaconda3\\envs\\tf1_env\\lib\\site-packages\\IPython\\core\\async_helpers.py\", line 78, in _pseudo_sync_runner\n",
      "    coro.send(None)\n",
      "  File \"C:\\Users\\thecl\\anaconda3\\envs\\tf1_env\\lib\\site-packages\\IPython\\core\\interactiveshell.py\", line 3186, in run_cell_async\n",
      "    interactivity=interactivity, compiler=compiler, result=result)\n",
      "  File \"C:\\Users\\thecl\\anaconda3\\envs\\tf1_env\\lib\\site-packages\\IPython\\core\\interactiveshell.py\", line 3396, in run_ast_nodes\n",
      "    self.showtraceback()\n",
      "  File \"C:\\Users\\thecl\\anaconda3\\envs\\tf1_env\\lib\\site-packages\\IPython\\core\\interactiveshell.py\", line 2080, in showtraceback\n",
      "    value, tb, tb_offset=tb_offset)\n",
      "  File \"C:\\Users\\thecl\\anaconda3\\envs\\tf1_env\\lib\\site-packages\\IPython\\core\\ultratb.py\", line 1368, in structured_traceback\n",
      "    self, etype, value, tb, tb_offset, number_of_lines_of_context)\n",
      "  File \"C:\\Users\\thecl\\anaconda3\\envs\\tf1_env\\lib\\site-packages\\IPython\\core\\ultratb.py\", line 1268, in structured_traceback\n",
      "    self, etype, value, tb, tb_offset, number_of_lines_of_context\n",
      "  File \"C:\\Users\\thecl\\anaconda3\\envs\\tf1_env\\lib\\site-packages\\IPython\\core\\ultratb.py\", line 1143, in structured_traceback\n",
      "    chained_exceptions_tb_offset)\n",
      "  File \"C:\\Users\\thecl\\anaconda3\\envs\\tf1_env\\lib\\site-packages\\IPython\\core\\ultratb.py\", line 1082, in format_exception_as_a_whole\n",
      "    last_unique, recursion_repeat = find_recursion(orig_etype, evalue, records)\n",
      "  File \"C:\\Users\\thecl\\anaconda3\\envs\\tf1_env\\lib\\site-packages\\IPython\\core\\ultratb.py\", line 382, in find_recursion\n",
      "    return len(records), 0\n",
      "TypeError: object of type 'NoneType' has no len()\n",
      "\n",
      "During handling of the above exception, another exception occurred:\n",
      "\n",
      "Traceback (most recent call last):\n",
      "  File \"C:\\Users\\thecl\\anaconda3\\envs\\tf1_env\\lib\\site-packages\\IPython\\core\\interactiveshell.py\", line 2077, in showtraceback\n",
      "    stb = value._render_traceback_()\n",
      "AttributeError: 'TypeError' object has no attribute '_render_traceback_'\n",
      "\n",
      "During handling of the above exception, another exception occurred:\n",
      "\n",
      "Traceback (most recent call last):\n",
      "  File \"C:\\Users\\thecl\\anaconda3\\envs\\tf1_env\\lib\\site-packages\\IPython\\core\\ultratb.py\", line 1101, in get_records\n",
      "    return _fixed_getinnerframes(etb, number_of_lines_of_context, tb_offset)\n",
      "  File \"C:\\Users\\thecl\\anaconda3\\envs\\tf1_env\\lib\\site-packages\\IPython\\core\\ultratb.py\", line 248, in wrapped\n",
      "    return f(*args, **kwargs)\n",
      "  File \"C:\\Users\\thecl\\anaconda3\\envs\\tf1_env\\lib\\site-packages\\IPython\\core\\ultratb.py\", line 281, in _fixed_getinnerframes\n",
      "    records = fix_frame_records_filenames(inspect.getinnerframes(etb, context))\n",
      "  File \"C:\\Users\\thecl\\anaconda3\\envs\\tf1_env\\lib\\inspect.py\", line 1500, in getinnerframes\n",
      "    frameinfo = (tb.tb_frame,) + getframeinfo(tb, context)\n",
      "  File \"C:\\Users\\thecl\\anaconda3\\envs\\tf1_env\\lib\\inspect.py\", line 1458, in getframeinfo\n",
      "    filename = getsourcefile(frame) or getfile(frame)\n",
      "  File \"C:\\Users\\thecl\\anaconda3\\envs\\tf1_env\\lib\\inspect.py\", line 696, in getsourcefile\n",
      "    if getattr(getmodule(object, filename), '__loader__', None) is not None:\n",
      "  File \"C:\\Users\\thecl\\anaconda3\\envs\\tf1_env\\lib\\inspect.py\", line 733, in getmodule\n",
      "    if ismodule(module) and hasattr(module, '__file__'):\n",
      "  File \"C:\\Users\\thecl\\anaconda3\\envs\\tf1_env\\lib\\site-packages\\tensorflow\\__init__.py\", line 50, in __getattr__\n",
      "    module = self._load()\n",
      "  File \"C:\\Users\\thecl\\anaconda3\\envs\\tf1_env\\lib\\site-packages\\tensorflow\\__init__.py\", line 44, in _load\n",
      "    module = _importlib.import_module(self.__name__)\n",
      "  File \"C:\\Users\\thecl\\anaconda3\\envs\\tf1_env\\lib\\importlib\\__init__.py\", line 127, in import_module\n",
      "    return _bootstrap._gcd_import(name[level:], package, level)\n",
      "  File \"<frozen importlib._bootstrap>\", line 1006, in _gcd_import\n",
      "  File \"<frozen importlib._bootstrap>\", line 983, in _find_and_load\n",
      "  File \"<frozen importlib._bootstrap>\", line 953, in _find_and_load_unlocked\n",
      "  File \"<frozen importlib._bootstrap>\", line 219, in _call_with_frames_removed\n",
      "  File \"<frozen importlib._bootstrap>\", line 1006, in _gcd_import\n",
      "  File \"<frozen importlib._bootstrap>\", line 983, in _find_and_load\n",
      "  File \"<frozen importlib._bootstrap>\", line 967, in _find_and_load_unlocked\n",
      "  File \"<frozen importlib._bootstrap>\", line 677, in _load_unlocked\n",
      "  File \"<frozen importlib._bootstrap_external>\", line 728, in exec_module\n",
      "  File \"<frozen importlib._bootstrap>\", line 219, in _call_with_frames_removed\n",
      "  File \"C:\\Users\\thecl\\anaconda3\\envs\\tf1_env\\lib\\site-packages\\tensorflow_core\\__init__.py\", line 33, in <module>\n",
      "    from tensorflow._api.v1 import audio\n",
      "  File \"C:\\Users\\thecl\\anaconda3\\envs\\tf1_env\\lib\\site-packages\\tensorflow_core\\_api\\v1\\audio\\__init__.py\", line 10, in <module>\n",
      "    from tensorflow.python.ops.gen_audio_ops import decode_wav\n",
      "  File \"C:\\Users\\thecl\\anaconda3\\envs\\tf1_env\\lib\\site-packages\\tensorflow_core\\python\\ops\\gen_audio_ops.py\", line 11, in <module>\n",
      "    from tensorflow.python.eager import context as _context\n",
      "  File \"C:\\Users\\thecl\\anaconda3\\envs\\tf1_env\\lib\\site-packages\\tensorflow_core\\python\\eager\\context.py\", line 29, in <module>\n",
      "    from tensorflow.core.protobuf import config_pb2\n",
      "  File \"C:\\Users\\thecl\\anaconda3\\envs\\tf1_env\\lib\\site-packages\\tensorflow_core\\core\\protobuf\\config_pb2.py\", line 16, in <module>\n",
      "    from tensorflow.core.framework import cost_graph_pb2 as tensorflow_dot_core_dot_framework_dot_cost__graph__pb2\n",
      "  File \"C:\\Users\\thecl\\anaconda3\\envs\\tf1_env\\lib\\site-packages\\tensorflow_core\\core\\framework\\cost_graph_pb2.py\", line 16, in <module>\n",
      "    from tensorflow.core.framework import tensor_shape_pb2 as tensorflow_dot_core_dot_framework_dot_tensor__shape__pb2\n",
      "  File \"C:\\Users\\thecl\\anaconda3\\envs\\tf1_env\\lib\\site-packages\\tensorflow_core\\core\\framework\\tensor_shape_pb2.py\", line 42, in <module>\n",
      "    serialized_options=None, file=DESCRIPTOR),\n",
      "  File \"C:\\Users\\thecl\\anaconda3\\envs\\tf1_env\\lib\\site-packages\\google\\protobuf\\descriptor.py\", line 561, in __new__\n",
      "    _message.Message._CheckCalledFromGeneratedFile()\n",
      "TypeError: Descriptors cannot not be created directly.\n",
      "If this call came from a _pb2.py file, your generated code is out of date and must be regenerated with protoc >= 3.19.0.\n",
      "If you cannot immediately regenerate your protos, some other possible workarounds are:\n",
      " 1. Downgrade the protobuf package to 3.20.x or lower.\n",
      " 2. Set PROTOCOL_BUFFERS_PYTHON_IMPLEMENTATION=python (but this will use pure-Python parsing and will be much slower).\n",
      "\n",
      "More information: https://developers.google.com/protocol-buffers/docs/news/2022-05-06#python-updates\n"
     ]
    }
   ],
   "source": [
    "import matplotlib\n",
    "import tensorflow as tf\n",
    "import tensorflow_estimator as tfe"
   ]
  },
  {
   "cell_type": "code",
   "execution_count": null,
   "metadata": {},
   "outputs": [
    {
     "name": "stderr",
     "output_type": "stream",
     "text": [
      "ERROR:root:Internal Python error in the inspect module.\n",
      "Below is the traceback from this internal error.\n",
      "\n",
      "ERROR:root:Internal Python error in the inspect module.\n",
      "Below is the traceback from this internal error.\n",
      "\n"
     ]
    },
    {
     "name": "stdout",
     "output_type": "stream",
     "text": [
      "Traceback (most recent call last):\n",
      "  File \"C:\\Users\\thecl\\anaconda3\\envs\\tf1_env\\lib\\site-packages\\IPython\\core\\interactiveshell.py\", line 3457, in run_code\n",
      "    exec(code_obj, self.user_global_ns, self.user_ns)\n",
      "  File \"C:\\Users\\thecl\\AppData\\Local\\Temp\\ipykernel_21112\\2524316434.py\", line 1, in <module>\n",
      "    classifier = tf.estimator.DNNClassifier(n_classes=2, hidden_units=[10, 20, 10], feature_columns = feat_cols)\n",
      "  File \"C:\\Users\\thecl\\anaconda3\\envs\\tf1_env\\lib\\site-packages\\tensorflow_core\\python\\util\\module_wrapper.py\", line 193, in __getattr__\n",
      "    attr = getattr(self._tfmw_wrapped_module, name)\n",
      "AttributeError: module 'tensorflow' has no attribute 'estimator'\n",
      "\n",
      "During handling of the above exception, another exception occurred:\n",
      "\n",
      "Traceback (most recent call last):\n",
      "  File \"C:\\Users\\thecl\\anaconda3\\envs\\tf1_env\\lib\\site-packages\\IPython\\core\\interactiveshell.py\", line 2077, in showtraceback\n",
      "    stb = value._render_traceback_()\n",
      "AttributeError: 'AttributeError' object has no attribute '_render_traceback_'\n",
      "\n",
      "During handling of the above exception, another exception occurred:\n",
      "\n",
      "Traceback (most recent call last):\n",
      "  File \"C:\\Users\\thecl\\anaconda3\\envs\\tf1_env\\lib\\site-packages\\IPython\\core\\ultratb.py\", line 1101, in get_records\n",
      "    return _fixed_getinnerframes(etb, number_of_lines_of_context, tb_offset)\n",
      "  File \"C:\\Users\\thecl\\anaconda3\\envs\\tf1_env\\lib\\site-packages\\IPython\\core\\ultratb.py\", line 248, in wrapped\n",
      "    return f(*args, **kwargs)\n",
      "  File \"C:\\Users\\thecl\\anaconda3\\envs\\tf1_env\\lib\\site-packages\\IPython\\core\\ultratb.py\", line 281, in _fixed_getinnerframes\n",
      "    records = fix_frame_records_filenames(inspect.getinnerframes(etb, context))\n",
      "  File \"C:\\Users\\thecl\\anaconda3\\envs\\tf1_env\\lib\\inspect.py\", line 1500, in getinnerframes\n",
      "    frameinfo = (tb.tb_frame,) + getframeinfo(tb, context)\n",
      "  File \"C:\\Users\\thecl\\anaconda3\\envs\\tf1_env\\lib\\inspect.py\", line 1458, in getframeinfo\n",
      "    filename = getsourcefile(frame) or getfile(frame)\n",
      "  File \"C:\\Users\\thecl\\anaconda3\\envs\\tf1_env\\lib\\inspect.py\", line 696, in getsourcefile\n",
      "    if getattr(getmodule(object, filename), '__loader__', None) is not None:\n",
      "  File \"C:\\Users\\thecl\\anaconda3\\envs\\tf1_env\\lib\\inspect.py\", line 733, in getmodule\n",
      "    if ismodule(module) and hasattr(module, '__file__'):\n",
      "  File \"C:\\Users\\thecl\\anaconda3\\envs\\tf1_env\\lib\\site-packages\\tensorflow\\__init__.py\", line 50, in __getattr__\n",
      "    module = self._load()\n",
      "  File \"C:\\Users\\thecl\\anaconda3\\envs\\tf1_env\\lib\\site-packages\\tensorflow\\__init__.py\", line 44, in _load\n",
      "    module = _importlib.import_module(self.__name__)\n",
      "  File \"C:\\Users\\thecl\\anaconda3\\envs\\tf1_env\\lib\\importlib\\__init__.py\", line 127, in import_module\n",
      "    return _bootstrap._gcd_import(name[level:], package, level)\n",
      "  File \"<frozen importlib._bootstrap>\", line 1006, in _gcd_import\n",
      "  File \"<frozen importlib._bootstrap>\", line 983, in _find_and_load\n",
      "  File \"<frozen importlib._bootstrap>\", line 953, in _find_and_load_unlocked\n",
      "  File \"<frozen importlib._bootstrap>\", line 219, in _call_with_frames_removed\n",
      "  File \"<frozen importlib._bootstrap>\", line 1006, in _gcd_import\n",
      "  File \"<frozen importlib._bootstrap>\", line 983, in _find_and_load\n",
      "  File \"<frozen importlib._bootstrap>\", line 967, in _find_and_load_unlocked\n",
      "  File \"<frozen importlib._bootstrap>\", line 677, in _load_unlocked\n",
      "  File \"<frozen importlib._bootstrap_external>\", line 728, in exec_module\n",
      "  File \"<frozen importlib._bootstrap>\", line 219, in _call_with_frames_removed\n",
      "  File \"C:\\Users\\thecl\\anaconda3\\envs\\tf1_env\\lib\\site-packages\\tensorflow_core\\__init__.py\", line 33, in <module>\n",
      "    from tensorflow._api.v1 import audio\n",
      "  File \"C:\\Users\\thecl\\anaconda3\\envs\\tf1_env\\lib\\site-packages\\tensorflow_core\\_api\\v1\\audio\\__init__.py\", line 10, in <module>\n",
      "    from tensorflow.python.ops.gen_audio_ops import decode_wav\n",
      "  File \"C:\\Users\\thecl\\anaconda3\\envs\\tf1_env\\lib\\site-packages\\tensorflow_core\\python\\ops\\gen_audio_ops.py\", line 11, in <module>\n",
      "    from tensorflow.python.eager import context as _context\n",
      "  File \"C:\\Users\\thecl\\anaconda3\\envs\\tf1_env\\lib\\site-packages\\tensorflow_core\\python\\eager\\context.py\", line 29, in <module>\n",
      "    from tensorflow.core.protobuf import config_pb2\n",
      "  File \"C:\\Users\\thecl\\anaconda3\\envs\\tf1_env\\lib\\site-packages\\tensorflow_core\\core\\protobuf\\config_pb2.py\", line 16, in <module>\n",
      "    from tensorflow.core.framework import cost_graph_pb2 as tensorflow_dot_core_dot_framework_dot_cost__graph__pb2\n",
      "  File \"C:\\Users\\thecl\\anaconda3\\envs\\tf1_env\\lib\\site-packages\\tensorflow_core\\core\\framework\\cost_graph_pb2.py\", line 16, in <module>\n",
      "    from tensorflow.core.framework import tensor_shape_pb2 as tensorflow_dot_core_dot_framework_dot_tensor__shape__pb2\n",
      "  File \"C:\\Users\\thecl\\anaconda3\\envs\\tf1_env\\lib\\site-packages\\tensorflow_core\\core\\framework\\tensor_shape_pb2.py\", line 42, in <module>\n",
      "    serialized_options=None, file=DESCRIPTOR),\n",
      "  File \"C:\\Users\\thecl\\anaconda3\\envs\\tf1_env\\lib\\site-packages\\google\\protobuf\\descriptor.py\", line 561, in __new__\n",
      "    _message.Message._CheckCalledFromGeneratedFile()\n",
      "TypeError: Descriptors cannot not be created directly.\n",
      "If this call came from a _pb2.py file, your generated code is out of date and must be regenerated with protoc >= 3.19.0.\n",
      "If you cannot immediately regenerate your protos, some other possible workarounds are:\n",
      " 1. Downgrade the protobuf package to 3.20.x or lower.\n",
      " 2. Set PROTOCOL_BUFFERS_PYTHON_IMPLEMENTATION=python (but this will use pure-Python parsing and will be much slower).\n",
      "\n",
      "More information: https://developers.google.com/protocol-buffers/docs/news/2022-05-06#python-updates\n",
      "ERROR! Session/line number was not unique in database. History logging moved to new session 71\n"
     ]
    },
    {
     "name": "stderr",
     "output_type": "stream",
     "text": [
      "ERROR:root:Internal Python error in the inspect module.\n",
      "Below is the traceback from this internal error.\n",
      "\n"
     ]
    },
    {
     "name": "stdout",
     "output_type": "stream",
     "text": [
      "Traceback (most recent call last):\n",
      "  File \"C:\\Users\\thecl\\anaconda3\\envs\\tf1_env\\lib\\site-packages\\IPython\\core\\interactiveshell.py\", line 3457, in run_code\n",
      "    exec(code_obj, self.user_global_ns, self.user_ns)\n",
      "  File \"C:\\Users\\thecl\\AppData\\Local\\Temp\\ipykernel_21112\\2524316434.py\", line 1, in <module>\n",
      "    classifier = tf.estimator.DNNClassifier(n_classes=2, hidden_units=[10, 20, 10], feature_columns = feat_cols)\n",
      "  File \"C:\\Users\\thecl\\anaconda3\\envs\\tf1_env\\lib\\site-packages\\tensorflow_core\\python\\util\\module_wrapper.py\", line 193, in __getattr__\n",
      "    attr = getattr(self._tfmw_wrapped_module, name)\n",
      "AttributeError: module 'tensorflow' has no attribute 'estimator'\n",
      "\n",
      "During handling of the above exception, another exception occurred:\n",
      "\n",
      "Traceback (most recent call last):\n",
      "  File \"C:\\Users\\thecl\\anaconda3\\envs\\tf1_env\\lib\\site-packages\\IPython\\core\\interactiveshell.py\", line 2077, in showtraceback\n",
      "    stb = value._render_traceback_()\n",
      "AttributeError: 'AttributeError' object has no attribute '_render_traceback_'\n",
      "\n",
      "During handling of the above exception, another exception occurred:\n",
      "\n",
      "Traceback (most recent call last):\n",
      "  File \"C:\\Users\\thecl\\anaconda3\\envs\\tf1_env\\lib\\site-packages\\IPython\\core\\interactiveshell.py\", line 3377, in run_ast_nodes\n",
      "    if (await self.run_code(code, result,  async_=asy)):\n",
      "  File \"C:\\Users\\thecl\\anaconda3\\envs\\tf1_env\\lib\\site-packages\\IPython\\core\\interactiveshell.py\", line 3474, in run_code\n",
      "    self.showtraceback(running_compiled_code=True)\n",
      "  File \"C:\\Users\\thecl\\anaconda3\\envs\\tf1_env\\lib\\site-packages\\IPython\\core\\interactiveshell.py\", line 2080, in showtraceback\n",
      "    value, tb, tb_offset=tb_offset)\n",
      "  File \"C:\\Users\\thecl\\anaconda3\\envs\\tf1_env\\lib\\site-packages\\IPython\\core\\ultratb.py\", line 1368, in structured_traceback\n",
      "    self, etype, value, tb, tb_offset, number_of_lines_of_context)\n",
      "  File \"C:\\Users\\thecl\\anaconda3\\envs\\tf1_env\\lib\\site-packages\\IPython\\core\\ultratb.py\", line 1268, in structured_traceback\n",
      "    self, etype, value, tb, tb_offset, number_of_lines_of_context\n",
      "  File \"C:\\Users\\thecl\\anaconda3\\envs\\tf1_env\\lib\\site-packages\\IPython\\core\\ultratb.py\", line 1125, in structured_traceback\n",
      "    tb_offset)\n",
      "  File \"C:\\Users\\thecl\\anaconda3\\envs\\tf1_env\\lib\\site-packages\\IPython\\core\\ultratb.py\", line 1082, in format_exception_as_a_whole\n",
      "    last_unique, recursion_repeat = find_recursion(orig_etype, evalue, records)\n",
      "  File \"C:\\Users\\thecl\\anaconda3\\envs\\tf1_env\\lib\\site-packages\\IPython\\core\\ultratb.py\", line 382, in find_recursion\n",
      "    return len(records), 0\n",
      "TypeError: object of type 'NoneType' has no len()\n",
      "\n",
      "During handling of the above exception, another exception occurred:\n",
      "\n",
      "Traceback (most recent call last):\n",
      "  File \"C:\\Users\\thecl\\anaconda3\\envs\\tf1_env\\lib\\site-packages\\IPython\\core\\interactiveshell.py\", line 2077, in showtraceback\n",
      "    stb = value._render_traceback_()\n",
      "AttributeError: 'TypeError' object has no attribute '_render_traceback_'\n",
      "\n",
      "During handling of the above exception, another exception occurred:\n",
      "\n",
      "Traceback (most recent call last):\n",
      "  File \"C:\\Users\\thecl\\anaconda3\\envs\\tf1_env\\lib\\site-packages\\IPython\\core\\ultratb.py\", line 1101, in get_records\n",
      "    return _fixed_getinnerframes(etb, number_of_lines_of_context, tb_offset)\n",
      "  File \"C:\\Users\\thecl\\anaconda3\\envs\\tf1_env\\lib\\site-packages\\IPython\\core\\ultratb.py\", line 248, in wrapped\n",
      "    return f(*args, **kwargs)\n",
      "  File \"C:\\Users\\thecl\\anaconda3\\envs\\tf1_env\\lib\\site-packages\\IPython\\core\\ultratb.py\", line 281, in _fixed_getinnerframes\n",
      "    records = fix_frame_records_filenames(inspect.getinnerframes(etb, context))\n",
      "  File \"C:\\Users\\thecl\\anaconda3\\envs\\tf1_env\\lib\\inspect.py\", line 1500, in getinnerframes\n",
      "    frameinfo = (tb.tb_frame,) + getframeinfo(tb, context)\n",
      "  File \"C:\\Users\\thecl\\anaconda3\\envs\\tf1_env\\lib\\inspect.py\", line 1458, in getframeinfo\n",
      "    filename = getsourcefile(frame) or getfile(frame)\n",
      "  File \"C:\\Users\\thecl\\anaconda3\\envs\\tf1_env\\lib\\inspect.py\", line 696, in getsourcefile\n",
      "    if getattr(getmodule(object, filename), '__loader__', None) is not None:\n",
      "  File \"C:\\Users\\thecl\\anaconda3\\envs\\tf1_env\\lib\\inspect.py\", line 733, in getmodule\n",
      "    if ismodule(module) and hasattr(module, '__file__'):\n",
      "  File \"C:\\Users\\thecl\\anaconda3\\envs\\tf1_env\\lib\\site-packages\\tensorflow\\__init__.py\", line 50, in __getattr__\n",
      "    module = self._load()\n",
      "  File \"C:\\Users\\thecl\\anaconda3\\envs\\tf1_env\\lib\\site-packages\\tensorflow\\__init__.py\", line 44, in _load\n",
      "    module = _importlib.import_module(self.__name__)\n",
      "  File \"C:\\Users\\thecl\\anaconda3\\envs\\tf1_env\\lib\\importlib\\__init__.py\", line 127, in import_module\n",
      "    return _bootstrap._gcd_import(name[level:], package, level)\n",
      "  File \"<frozen importlib._bootstrap>\", line 1006, in _gcd_import\n",
      "  File \"<frozen importlib._bootstrap>\", line 983, in _find_and_load\n",
      "  File \"<frozen importlib._bootstrap>\", line 953, in _find_and_load_unlocked\n",
      "  File \"<frozen importlib._bootstrap>\", line 219, in _call_with_frames_removed\n",
      "  File \"<frozen importlib._bootstrap>\", line 1006, in _gcd_import\n",
      "  File \"<frozen importlib._bootstrap>\", line 983, in _find_and_load\n",
      "  File \"<frozen importlib._bootstrap>\", line 967, in _find_and_load_unlocked\n",
      "  File \"<frozen importlib._bootstrap>\", line 677, in _load_unlocked\n",
      "  File \"<frozen importlib._bootstrap_external>\", line 728, in exec_module\n",
      "  File \"<frozen importlib._bootstrap>\", line 219, in _call_with_frames_removed\n",
      "  File \"C:\\Users\\thecl\\anaconda3\\envs\\tf1_env\\lib\\site-packages\\tensorflow_core\\__init__.py\", line 33, in <module>\n",
      "    from tensorflow._api.v1 import audio\n",
      "  File \"C:\\Users\\thecl\\anaconda3\\envs\\tf1_env\\lib\\site-packages\\tensorflow_core\\_api\\v1\\audio\\__init__.py\", line 10, in <module>\n",
      "    from tensorflow.python.ops.gen_audio_ops import decode_wav\n",
      "  File \"C:\\Users\\thecl\\anaconda3\\envs\\tf1_env\\lib\\site-packages\\tensorflow_core\\python\\ops\\gen_audio_ops.py\", line 11, in <module>\n",
      "    from tensorflow.python.eager import context as _context\n",
      "  File \"C:\\Users\\thecl\\anaconda3\\envs\\tf1_env\\lib\\site-packages\\tensorflow_core\\python\\eager\\context.py\", line 29, in <module>\n",
      "    from tensorflow.core.protobuf import config_pb2\n",
      "  File \"C:\\Users\\thecl\\anaconda3\\envs\\tf1_env\\lib\\site-packages\\tensorflow_core\\core\\protobuf\\config_pb2.py\", line 16, in <module>\n",
      "    from tensorflow.core.framework import cost_graph_pb2 as tensorflow_dot_core_dot_framework_dot_cost__graph__pb2\n",
      "  File \"C:\\Users\\thecl\\anaconda3\\envs\\tf1_env\\lib\\site-packages\\tensorflow_core\\core\\framework\\cost_graph_pb2.py\", line 16, in <module>\n",
      "    from tensorflow.core.framework import tensor_shape_pb2 as tensorflow_dot_core_dot_framework_dot_tensor__shape__pb2\n",
      "  File \"C:\\Users\\thecl\\anaconda3\\envs\\tf1_env\\lib\\site-packages\\tensorflow_core\\core\\framework\\tensor_shape_pb2.py\", line 42, in <module>\n",
      "    serialized_options=None, file=DESCRIPTOR),\n",
      "  File \"C:\\Users\\thecl\\anaconda3\\envs\\tf1_env\\lib\\site-packages\\google\\protobuf\\descriptor.py\", line 561, in __new__\n",
      "    _message.Message._CheckCalledFromGeneratedFile()\n",
      "TypeError: Descriptors cannot not be created directly.\n",
      "If this call came from a _pb2.py file, your generated code is out of date and must be regenerated with protoc >= 3.19.0.\n",
      "If you cannot immediately regenerate your protos, some other possible workarounds are:\n",
      " 1. Downgrade the protobuf package to 3.20.x or lower.\n",
      " 2. Set PROTOCOL_BUFFERS_PYTHON_IMPLEMENTATION=python (but this will use pure-Python parsing and will be much slower).\n",
      "\n",
      "More information: https://developers.google.com/protocol-buffers/docs/news/2022-05-06#python-updates\n",
      "Traceback (most recent call last):\n",
      "  File \"C:\\Users\\thecl\\anaconda3\\envs\\tf1_env\\lib\\site-packages\\IPython\\core\\interactiveshell.py\", line 3457, in run_code\n",
      "    exec(code_obj, self.user_global_ns, self.user_ns)\n",
      "  File \"C:\\Users\\thecl\\AppData\\Local\\Temp\\ipykernel_21112\\2524316434.py\", line 1, in <module>\n",
      "    classifier = tf.estimator.DNNClassifier(n_classes=2, hidden_units=[10, 20, 10], feature_columns = feat_cols)\n",
      "  File \"C:\\Users\\thecl\\anaconda3\\envs\\tf1_env\\lib\\site-packages\\tensorflow_core\\python\\util\\module_wrapper.py\", line 193, in __getattr__\n",
      "    attr = getattr(self._tfmw_wrapped_module, name)\n",
      "AttributeError: module 'tensorflow' has no attribute 'estimator'\n",
      "\n",
      "During handling of the above exception, another exception occurred:\n",
      "\n",
      "Traceback (most recent call last):\n",
      "  File \"C:\\Users\\thecl\\anaconda3\\envs\\tf1_env\\lib\\site-packages\\IPython\\core\\interactiveshell.py\", line 2077, in showtraceback\n",
      "    stb = value._render_traceback_()\n",
      "AttributeError: 'AttributeError' object has no attribute '_render_traceback_'\n",
      "\n",
      "During handling of the above exception, another exception occurred:\n",
      "\n",
      "Traceback (most recent call last):\n",
      "  File \"C:\\Users\\thecl\\anaconda3\\envs\\tf1_env\\lib\\site-packages\\IPython\\core\\interactiveshell.py\", line 3377, in run_ast_nodes\n",
      "    if (await self.run_code(code, result,  async_=asy)):\n",
      "  File \"C:\\Users\\thecl\\anaconda3\\envs\\tf1_env\\lib\\site-packages\\IPython\\core\\interactiveshell.py\", line 3474, in run_code\n",
      "    self.showtraceback(running_compiled_code=True)\n",
      "  File \"C:\\Users\\thecl\\anaconda3\\envs\\tf1_env\\lib\\site-packages\\IPython\\core\\interactiveshell.py\", line 2080, in showtraceback\n",
      "    value, tb, tb_offset=tb_offset)\n",
      "  File \"C:\\Users\\thecl\\anaconda3\\envs\\tf1_env\\lib\\site-packages\\IPython\\core\\ultratb.py\", line 1368, in structured_traceback\n",
      "    self, etype, value, tb, tb_offset, number_of_lines_of_context)\n",
      "  File \"C:\\Users\\thecl\\anaconda3\\envs\\tf1_env\\lib\\site-packages\\IPython\\core\\ultratb.py\", line 1268, in structured_traceback\n",
      "    self, etype, value, tb, tb_offset, number_of_lines_of_context\n",
      "  File \"C:\\Users\\thecl\\anaconda3\\envs\\tf1_env\\lib\\site-packages\\IPython\\core\\ultratb.py\", line 1125, in structured_traceback\n",
      "    tb_offset)\n",
      "  File \"C:\\Users\\thecl\\anaconda3\\envs\\tf1_env\\lib\\site-packages\\IPython\\core\\ultratb.py\", line 1082, in format_exception_as_a_whole\n",
      "    last_unique, recursion_repeat = find_recursion(orig_etype, evalue, records)\n",
      "  File \"C:\\Users\\thecl\\anaconda3\\envs\\tf1_env\\lib\\site-packages\\IPython\\core\\ultratb.py\", line 382, in find_recursion\n",
      "    return len(records), 0\n",
      "TypeError: object of type 'NoneType' has no len()\n",
      "\n",
      "During handling of the above exception, another exception occurred:\n",
      "\n",
      "Traceback (most recent call last):\n",
      "  File \"C:\\Users\\thecl\\anaconda3\\envs\\tf1_env\\lib\\site-packages\\IPython\\core\\interactiveshell.py\", line 2077, in showtraceback\n",
      "    stb = value._render_traceback_()\n",
      "AttributeError: 'TypeError' object has no attribute '_render_traceback_'\n",
      "\n",
      "During handling of the above exception, another exception occurred:\n",
      "\n",
      "Traceback (most recent call last):\n",
      "  File \"C:\\Users\\thecl\\anaconda3\\envs\\tf1_env\\lib\\site-packages\\IPython\\core\\interactiveshell.py\", line 2960, in _run_cell\n",
      "    return runner(coro)\n",
      "  File \"C:\\Users\\thecl\\anaconda3\\envs\\tf1_env\\lib\\site-packages\\IPython\\core\\async_helpers.py\", line 78, in _pseudo_sync_runner\n",
      "    coro.send(None)\n",
      "  File \"C:\\Users\\thecl\\anaconda3\\envs\\tf1_env\\lib\\site-packages\\IPython\\core\\interactiveshell.py\", line 3186, in run_cell_async\n",
      "    interactivity=interactivity, compiler=compiler, result=result)\n",
      "  File \"C:\\Users\\thecl\\anaconda3\\envs\\tf1_env\\lib\\site-packages\\IPython\\core\\interactiveshell.py\", line 3396, in run_ast_nodes\n",
      "    self.showtraceback()\n",
      "  File \"C:\\Users\\thecl\\anaconda3\\envs\\tf1_env\\lib\\site-packages\\IPython\\core\\interactiveshell.py\", line 2080, in showtraceback\n",
      "    value, tb, tb_offset=tb_offset)\n",
      "  File \"C:\\Users\\thecl\\anaconda3\\envs\\tf1_env\\lib\\site-packages\\IPython\\core\\ultratb.py\", line 1368, in structured_traceback\n",
      "    self, etype, value, tb, tb_offset, number_of_lines_of_context)\n",
      "  File \"C:\\Users\\thecl\\anaconda3\\envs\\tf1_env\\lib\\site-packages\\IPython\\core\\ultratb.py\", line 1268, in structured_traceback\n",
      "    self, etype, value, tb, tb_offset, number_of_lines_of_context\n",
      "  File \"C:\\Users\\thecl\\anaconda3\\envs\\tf1_env\\lib\\site-packages\\IPython\\core\\ultratb.py\", line 1143, in structured_traceback\n",
      "    chained_exceptions_tb_offset)\n",
      "  File \"C:\\Users\\thecl\\anaconda3\\envs\\tf1_env\\lib\\site-packages\\IPython\\core\\ultratb.py\", line 1082, in format_exception_as_a_whole\n",
      "    last_unique, recursion_repeat = find_recursion(orig_etype, evalue, records)\n",
      "  File \"C:\\Users\\thecl\\anaconda3\\envs\\tf1_env\\lib\\site-packages\\IPython\\core\\ultratb.py\", line 382, in find_recursion\n",
      "    return len(records), 0\n",
      "TypeError: object of type 'NoneType' has no len()\n",
      "\n",
      "During handling of the above exception, another exception occurred:\n",
      "\n",
      "Traceback (most recent call last):\n",
      "  File \"C:\\Users\\thecl\\anaconda3\\envs\\tf1_env\\lib\\site-packages\\IPython\\core\\interactiveshell.py\", line 2077, in showtraceback\n",
      "    stb = value._render_traceback_()\n",
      "AttributeError: 'TypeError' object has no attribute '_render_traceback_'\n",
      "\n",
      "During handling of the above exception, another exception occurred:\n",
      "\n",
      "Traceback (most recent call last):\n",
      "  File \"C:\\Users\\thecl\\anaconda3\\envs\\tf1_env\\lib\\site-packages\\IPython\\core\\ultratb.py\", line 1101, in get_records\n",
      "    return _fixed_getinnerframes(etb, number_of_lines_of_context, tb_offset)\n",
      "  File \"C:\\Users\\thecl\\anaconda3\\envs\\tf1_env\\lib\\site-packages\\IPython\\core\\ultratb.py\", line 248, in wrapped\n",
      "    return f(*args, **kwargs)\n",
      "  File \"C:\\Users\\thecl\\anaconda3\\envs\\tf1_env\\lib\\site-packages\\IPython\\core\\ultratb.py\", line 281, in _fixed_getinnerframes\n",
      "    records = fix_frame_records_filenames(inspect.getinnerframes(etb, context))\n",
      "  File \"C:\\Users\\thecl\\anaconda3\\envs\\tf1_env\\lib\\inspect.py\", line 1500, in getinnerframes\n",
      "    frameinfo = (tb.tb_frame,) + getframeinfo(tb, context)\n",
      "  File \"C:\\Users\\thecl\\anaconda3\\envs\\tf1_env\\lib\\inspect.py\", line 1458, in getframeinfo\n",
      "    filename = getsourcefile(frame) or getfile(frame)\n",
      "  File \"C:\\Users\\thecl\\anaconda3\\envs\\tf1_env\\lib\\inspect.py\", line 696, in getsourcefile\n",
      "    if getattr(getmodule(object, filename), '__loader__', None) is not None:\n",
      "  File \"C:\\Users\\thecl\\anaconda3\\envs\\tf1_env\\lib\\inspect.py\", line 733, in getmodule\n",
      "    if ismodule(module) and hasattr(module, '__file__'):\n",
      "  File \"C:\\Users\\thecl\\anaconda3\\envs\\tf1_env\\lib\\site-packages\\tensorflow\\__init__.py\", line 50, in __getattr__\n",
      "    module = self._load()\n",
      "  File \"C:\\Users\\thecl\\anaconda3\\envs\\tf1_env\\lib\\site-packages\\tensorflow\\__init__.py\", line 44, in _load\n",
      "    module = _importlib.import_module(self.__name__)\n",
      "  File \"C:\\Users\\thecl\\anaconda3\\envs\\tf1_env\\lib\\importlib\\__init__.py\", line 127, in import_module\n",
      "    return _bootstrap._gcd_import(name[level:], package, level)\n",
      "  File \"<frozen importlib._bootstrap>\", line 1006, in _gcd_import\n",
      "  File \"<frozen importlib._bootstrap>\", line 983, in _find_and_load\n",
      "  File \"<frozen importlib._bootstrap>\", line 953, in _find_and_load_unlocked\n",
      "  File \"<frozen importlib._bootstrap>\", line 219, in _call_with_frames_removed\n",
      "  File \"<frozen importlib._bootstrap>\", line 1006, in _gcd_import\n",
      "  File \"<frozen importlib._bootstrap>\", line 983, in _find_and_load\n",
      "  File \"<frozen importlib._bootstrap>\", line 967, in _find_and_load_unlocked\n",
      "  File \"<frozen importlib._bootstrap>\", line 677, in _load_unlocked\n",
      "  File \"<frozen importlib._bootstrap_external>\", line 728, in exec_module\n",
      "  File \"<frozen importlib._bootstrap>\", line 219, in _call_with_frames_removed\n",
      "  File \"C:\\Users\\thecl\\anaconda3\\envs\\tf1_env\\lib\\site-packages\\tensorflow_core\\__init__.py\", line 33, in <module>\n",
      "    from tensorflow._api.v1 import audio\n",
      "  File \"C:\\Users\\thecl\\anaconda3\\envs\\tf1_env\\lib\\site-packages\\tensorflow_core\\_api\\v1\\audio\\__init__.py\", line 10, in <module>\n",
      "    from tensorflow.python.ops.gen_audio_ops import decode_wav\n",
      "  File \"C:\\Users\\thecl\\anaconda3\\envs\\tf1_env\\lib\\site-packages\\tensorflow_core\\python\\ops\\gen_audio_ops.py\", line 11, in <module>\n",
      "    from tensorflow.python.eager import context as _context\n",
      "  File \"C:\\Users\\thecl\\anaconda3\\envs\\tf1_env\\lib\\site-packages\\tensorflow_core\\python\\eager\\context.py\", line 29, in <module>\n",
      "    from tensorflow.core.protobuf import config_pb2\n",
      "  File \"C:\\Users\\thecl\\anaconda3\\envs\\tf1_env\\lib\\site-packages\\tensorflow_core\\core\\protobuf\\config_pb2.py\", line 16, in <module>\n",
      "    from tensorflow.core.framework import cost_graph_pb2 as tensorflow_dot_core_dot_framework_dot_cost__graph__pb2\n",
      "  File \"C:\\Users\\thecl\\anaconda3\\envs\\tf1_env\\lib\\site-packages\\tensorflow_core\\core\\framework\\cost_graph_pb2.py\", line 16, in <module>\n",
      "    from tensorflow.core.framework import tensor_shape_pb2 as tensorflow_dot_core_dot_framework_dot_tensor__shape__pb2\n",
      "  File \"C:\\Users\\thecl\\anaconda3\\envs\\tf1_env\\lib\\site-packages\\tensorflow_core\\core\\framework\\tensor_shape_pb2.py\", line 42, in <module>\n",
      "    serialized_options=None, file=DESCRIPTOR),\n",
      "  File \"C:\\Users\\thecl\\anaconda3\\envs\\tf1_env\\lib\\site-packages\\google\\protobuf\\descriptor.py\", line 561, in __new__\n",
      "    _message.Message._CheckCalledFromGeneratedFile()\n",
      "TypeError: Descriptors cannot not be created directly.\n",
      "If this call came from a _pb2.py file, your generated code is out of date and must be regenerated with protoc >= 3.19.0.\n",
      "If you cannot immediately regenerate your protos, some other possible workarounds are:\n",
      " 1. Downgrade the protobuf package to 3.20.x or lower.\n",
      " 2. Set PROTOCOL_BUFFERS_PYTHON_IMPLEMENTATION=python (but this will use pure-Python parsing and will be much slower).\n",
      "\n",
      "More information: https://developers.google.com/protocol-buffers/docs/news/2022-05-06#python-updates\n"
     ]
    }
   ],
   "source": [
    "classifier = tf.estimator.DNNClassifier(n_classes=2, hidden_units=[10, 20, 10], feature_columns = feat_cols)"
   ]
  },
  {
   "cell_type": "markdown",
   "metadata": {},
   "source": [
    "** Create an object called classifier which is a DNNClassifier from learn. Set it to have 2 classes and a [10,20,10] hidden unit layer structure:**"
   ]
  },
  {
   "cell_type": "code",
   "execution_count": null,
   "metadata": {},
   "outputs": [],
   "source": []
  },
  {
   "cell_type": "markdown",
   "metadata": {},
   "source": [
    "** Now create a tf.estimator.pandas_input_fn that takes in your X_train, y_train, batch_size and set shuffle=True. You can play around with the batch_size parameter if you want, but let's start by setting it to 20 since our data isn't very big. **"
   ]
  },
  {
   "cell_type": "code",
   "execution_count": null,
   "metadata": {
    "jupyter": {
     "outputs_hidden": true
    }
   },
   "outputs": [],
   "source": []
  },
  {
   "cell_type": "markdown",
   "metadata": {},
   "source": [
    "** Now train classifier to the input function. Use steps=500. You can play around with these values if you want!**\n",
    "\n",
    "*Note: Ignore any warnings you get, they won't effect your output*"
   ]
  },
  {
   "cell_type": "code",
   "execution_count": null,
   "metadata": {},
   "outputs": [],
   "source": []
  },
  {
   "cell_type": "markdown",
   "metadata": {},
   "source": [
    "## Model Evaluation"
   ]
  },
  {
   "cell_type": "markdown",
   "metadata": {},
   "source": [
    "** Create another pandas_input_fn that takes in the X_test data for x. Remember this one won't need any y_test info since we will be using this for the network to create its own predictions. Set shuffle=False since we don't need to shuffle for predictions.**"
   ]
  },
  {
   "cell_type": "code",
   "execution_count": null,
   "metadata": {
    "jupyter": {
     "outputs_hidden": true
    }
   },
   "outputs": [],
   "source": []
  },
  {
   "cell_type": "markdown",
   "metadata": {},
   "source": [
    "** Use the predict method from the classifier model to create predictions from X_test **"
   ]
  },
  {
   "cell_type": "code",
   "execution_count": null,
   "metadata": {},
   "outputs": [],
   "source": []
  },
  {
   "cell_type": "code",
   "execution_count": null,
   "metadata": {},
   "outputs": [],
   "source": []
  },
  {
   "cell_type": "code",
   "execution_count": null,
   "metadata": {
    "jupyter": {
     "outputs_hidden": true
    }
   },
   "outputs": [],
   "source": []
  },
  {
   "cell_type": "markdown",
   "metadata": {},
   "source": [
    "** Now create a classification report and a Confusion Matrix. Does anything stand out to you?**"
   ]
  },
  {
   "cell_type": "code",
   "execution_count": null,
   "metadata": {
    "jupyter": {
     "outputs_hidden": true
    }
   },
   "outputs": [],
   "source": []
  },
  {
   "cell_type": "code",
   "execution_count": null,
   "metadata": {},
   "outputs": [],
   "source": []
  },
  {
   "cell_type": "code",
   "execution_count": null,
   "metadata": {
    "scrolled": true
   },
   "outputs": [],
   "source": []
  },
  {
   "cell_type": "markdown",
   "metadata": {},
   "source": [
    "## Optional Comparison\n",
    "\n",
    "** You should have noticed extremely accurate results from the DNN model. Let's compare this to a Random Forest Classifier for a reality check!**\n",
    "\n",
    "**Use SciKit Learn to Create a Random Forest Classifier and compare the confusion matrix and classification report to the DNN model**"
   ]
  },
  {
   "cell_type": "code",
   "execution_count": null,
   "metadata": {
    "jupyter": {
     "outputs_hidden": true
    }
   },
   "outputs": [],
   "source": []
  },
  {
   "cell_type": "code",
   "execution_count": null,
   "metadata": {
    "jupyter": {
     "outputs_hidden": true
    }
   },
   "outputs": [],
   "source": []
  },
  {
   "cell_type": "code",
   "execution_count": null,
   "metadata": {},
   "outputs": [],
   "source": []
  },
  {
   "cell_type": "code",
   "execution_count": null,
   "metadata": {
    "jupyter": {
     "outputs_hidden": true
    }
   },
   "outputs": [],
   "source": []
  },
  {
   "cell_type": "code",
   "execution_count": null,
   "metadata": {},
   "outputs": [],
   "source": []
  },
  {
   "cell_type": "code",
   "execution_count": null,
   "metadata": {},
   "outputs": [],
   "source": []
  },
  {
   "cell_type": "markdown",
   "metadata": {},
   "source": [
    "** It should have also done very well, possibly perfect! Hopefully you have seen the power of DNN! **"
   ]
  },
  {
   "cell_type": "markdown",
   "metadata": {},
   "source": [
    "# Great Job!"
   ]
  }
 ],
 "metadata": {
  "kernelspec": {
   "display_name": "Python 3 (ipykernel)",
   "language": "python",
   "name": "python3"
  },
  "language_info": {
   "codemirror_mode": {
    "name": "ipython",
    "version": 3
   },
   "file_extension": ".py",
   "mimetype": "text/x-python",
   "name": "python",
   "nbconvert_exporter": "python",
   "pygments_lexer": "ipython3",
   "version": "3.7.1"
  }
 },
 "nbformat": 4,
 "nbformat_minor": 4
}
